Workbook

Sheet Classifica
A1: Giocatore | B1: Punti Totali | C1: Posizione
A2: Dani | B2: =SUM('Giornata 1:Giornata 38'!M12) -> 28 | C2: =RANK(B2,$B$2:$B$5,0) -> 1
A3: Ale | B3: =SUM('Giornata 1:Giornata 38'!L12) -> 22 | C3: =RANK(B3,$B$2:$B$5,0) -> 2
A4: Mando | B4: =SUM('Giornata 1:Giornata 38'!O12) -> 16 | C4: =RANK(B4,$B$2:$B$5,0) -> 3
A5: Dipa | B5: =SUM('Giornata 1:Giornata 38'!N12) -> 13 | C5: =RANK(B5,$B$2:$B$5,0) -> 4

Sheet Giornata 1
A1: Partita | B1: Gol Casa Reale | C1: Gol Ospite Reale | D1: Ale Casa | E1: Ale Ospite | F1: Dani Casa | G1: Dani Ospite | H1: Dipa Casa | I1: Dipa Ospite | J1: Mando Casa | K1: Mando Ospite | L1: Punti Ale | M1: Punti Dani | N1: Punti Dipa | O1: Punti Mando
A2: Atalanta-Sassuolo | B2: 2 | C2: 1 | D2: 1 | E2: 0 | F2: 1 | G2: 1 | H2: 2 | I2: 1 | J2: 1 | K2: 1 | L2: =IF(OR($B2="",$C2="",D2="",E2=""),"",IF(AND(D2=$B2,E2=$C2),INDEX(Parametri!$B:$B,MATCH("Punti Risultato Esatto",Parametri!$A:$A,0)),IF(SIGN($B2-$C2)=SIGN(D2-E2),INDEX(Parametri!$B:$B,MATCH("Punti Solo Segno",Parametri!$A:$A,0)),0))+IF(AND(SIGN($B2-$C2)=SIGN(D2-E2),(--(SIGN(D2-E2)=SIGN($B2-$C2))+--(SIGN(F2-G2)=SIGN($B2-$C2))+--(SIGN(H2-I2)=SIGN($B2-$C2))+--(SIGN(J2-K2)=SIGN($B2-$C2)))=1),INDEX(Parametri!$B:$B,MATCH("Punti Bonus Unico",Parametri!$A:$A,0)),0)) -> 1 | M2: =IF(OR($B2="",$C2="",F2="",G2=""),"",IF(AND(F2=$B2,G2=$C2),INDEX(Parametri!$B:$B,MATCH("Punti Risultato Esatto",Parametri!$A:$A,0)),IF(SIGN($B2-$C2)=SIGN(F2-G2),INDEX(Parametri!$B:$B,MATCH("Punti Solo Segno",Parametri!$A:$A,0)),0))+IF(AND(SIGN($B2-$C2)=SIGN(F2-G2),(--(SIGN(D2-E2)=SIGN($B2-$C2))+--(SIGN(F2-G2)=SIGN($B2-$C2))+--(SIGN(H2-I2)=SIGN($B2-$C2))+--(SIGN(J2-K2)=SIGN($B2-$C2)))=1),INDEX(Parametri!$B:$B,MATCH("Punti Bonus Unico",Parametri!$A:$A,0)),0)) -> 0 | N2: =IF(OR($B2="",$C2="",H2="",I2=""),"",IF(AND(H2=$B2,I2=$C2),INDEX(Parametri!$B:$B,MATCH("Punti Risultato Esatto",Parametri!$A:$A,0)),IF(SIGN($B2-$C2)=SIGN(H2-I2),INDEX(Parametri!$B:$B,MATCH("Punti Solo Segno",Parametri!$A:$A,0)),0))+IF(AND(SIGN($B2-$C2)=SIGN(H2-I2),(--(SIGN(D2-E2)=SIGN($B2-$C2))+--(SIGN(F2-G2)=SIGN($B2-$C2))+--(SIGN(H2-I2)=SIGN($B2-$C2))+--(SIGN(J2-K2)=SIGN($B2-$C2)))=1),INDEX(Parametri!$B:$B,MATCH("Punti Bonus Unico",Parametri!$A:$A,0)),0)) -> 2 | O2: =IF(OR($B2="",$C2="",J2="",K2=""),"",IF(AND(J2=$B2,K2=$C2),INDEX(Parametri!$B:$B,MATCH("Punti Risultato Esatto",Parametri!$A:$A,0)),IF(SIGN($B2-$C2)=SIGN(J2-K2),INDEX(Parametri!$B:$B,MATCH("Punti Solo Segno",Parametri!$A:$A,0)),0))+IF(AND(SIGN($B2-$C2)=SIGN(J2-K2),(--(SIGN(D2-E2)=SIGN($B2-$C2))+--(SIGN(F2-G2)=SIGN($B2-$C2))+--(SIGN(H2-I2)=SIGN($B2-$C2))+--(SIGN(J2-K2)=SIGN($B2-$C2)))=1),INDEX(Parametri!$B:$B,MATCH("Punti Bonus Unico",Parametri!$A:$A,0)),0)) -> 0
A3: Bologna-Lazio | B3: 0 | C3: 1 | D3: 2 | E3: 0 | F3: 0 | G3: 2 | H3: 1 | I3: 1 | J3: 2 | K3: 1 | L3: =IF(OR($B3="",$C3="",D3="",E3=""),"",IF(AND(D3=$B3,E3=$C3),INDEX(Parametri!$B:$B,MATCH("Punti Risultato Esatto",Parametri!$A:$A,0)),IF(SIGN($B3-$C3)=SIGN(D3-E3),INDEX(Parametri!$B:$B,MATCH("Punti Solo Segno",Parametri!$A:$A,0)),0))+IF(AND(SIGN($B3-$C3)=SIGN(D3-E3),(--(SIGN(D3-E3)=SIGN($B3-$C3))+--(SIGN(F3-G3)=SIGN($B3-$C3))+--(SIGN(H3-I3)=SIGN($B3-$C3))+--(SIGN(J3-K3)=SIGN($B3-$C3)))=1),INDEX(Parametri!$B:$B,MATCH("Punti Bonus Unico",Parametri!$A:$A,0)),0)) -> 0 | M3: =IF(OR($B3="",$C3="",F3="",G3=""),"",IF(AND(F3=$B3,G3=$C3),INDEX(Parametri!$B:$B,MATCH("Punti Risultato Esatto",Parametri!$A:$A,0)),IF(SIGN($B3-$C3)=SIGN(F3-G3),INDEX(Parametri!$B:$B,MATCH("Punti Solo Segno",Parametri!$A:$A,0)),0))+IF(AND(SIGN($B3-$C3)=SIGN(F3-G3),(--(SIGN(D3-E3)=SIGN($B3-$C3))+--(SIGN(F3-G3)=SIGN($B3-$C3))+--(SIGN(H3-I3)=SIGN($B3-$C3))+--(SIGN(J3-K3)=SIGN($B3-$C3)))=1),INDEX(Parametri!$B:$B,MATCH("Punti Bonus Unico",Parametri!$A:$A,0)),0)) -> 4 | N3: =IF(OR($B3="",$C3="",H3="",I3=""),"",IF(AND(H3=$B3,I3=$C3),INDEX(Parametri!$B:$B,MATCH("Punti Risultato Esatto",Parametri!$A:$A,0)),IF(SIGN($B3-$C3)=SIGN(H3-I3),INDEX(Parametri!$B:$B,MATCH("Punti Solo Segno",Parametri!$A:$A,0)),0))+IF(AND(SIGN($B3-$C3)=SIGN(H3-I3),(--(SIGN(D3-E3)=SIGN($B3-$C3))+--(SIGN(F3-G3)=SIGN($B3-$C3))+--(SIGN(H3-I3)=SIGN($B3-$C3))+--(SIGN(J3-K3)=SIGN($B3-$C3)))=1),INDEX(Parametri!$B:$B,MATCH("Punti Bonus Unico",Parametri!$A:$A,0)),0)) -> 0 | O3: =IF(OR($B3="",$C3="",J3="",K3=""),"",IF(AND(J3=$B3,K3=$C3),INDEX(Parametri!$B:$B,MATCH("Punti Risultato Esatto",Parametri!$A:$A,0)),IF(SIGN($B3-$C3)=SIGN(J3-K3),INDEX(Parametri!$B:$B,MATCH("Punti Solo Segno",Parametri!$A:$A,0)),0))+IF(AND(SIGN($B3-$C3)=SIGN(J3-K3),(--(SIGN(D3-E3)=SIGN($B3-$C3))+--(SIGN(F3-G3)=SIGN($B3-$C3))+--(SIGN(H3-I3)=SIGN($B3-$C3))+--(SIGN(J3-K3)=SIGN($B3-$C3)))=1),INDEX(Parametri!$B:$B,MATCH("Punti Bonus Unico",Parametri!$A:$A,0)),0)) -> 0
A4: Frosinone-Juventus | B4: 0 | C4: 1 | D4: 0 | E4: 2 | F4: 1 | G4: 2 | H4: 0 | I4: 2 | J4: 0 | K4: 2 | L4: =IF(OR($B4="",$C4="",D4="",E4=""),"",IF(AND(D4=$B4,E4=$C4),INDEX(Parametri!$B:$B,MATCH("Punti Risultato Esatto",Parametri!$A:$A,0)),IF(SIGN($B4-$C4)=SIGN(D4-E4),INDEX(Parametri!$B:$B,MATCH("Punti Solo Segno",Parametri!$A:$A,0)),0))+IF(AND(SIGN($B4-$C4)=SIGN(D4-E4),(--(SIGN(D4-E4)=SIGN($B4-$C4))+--(SIGN(F4-G4)=SIGN($B4-$C4))+--(SIGN(H4-I4)=SIGN($B4-$C4))+--(SIGN(J4-K4)=SIGN($B4-$C4)))=1),INDEX(Parametri!$B:$B,MATCH("Punti Bonus Unico",Parametri!$A:$A,0)),0)) -> 1 | M4: =IF(OR($B4="",$C4="",F4="",G4=""),"",IF(AND(F4=$B4,G4=$C4),INDEX(Parametri!$B:$B,MATCH("Punti Risultato Esatto",Parametri!$A:$A,0)),IF(SIGN($B4-$C4)=SIGN(F4-G4),INDEX(Parametri!$B:$B,MATCH("Punti Solo Segno",Parametri!$A:$A,0)),0))+IF(AND(SIGN($B4-$C4)=SIGN(F4-G4),(--(SIGN(D4-E4)=SIGN($B4-$C4))+--(SIGN(F4-G4)=SIGN($B4-$C4))+--(SIGN(H4-I4)=SIGN($B4-$C4))+--(SIGN(J4-K4)=SIGN($B4-$C4)))=1),INDEX(Parametri!$B:$B,MATCH("Punti Bonus Unico",Parametri!$A:$A,0)),0)) -> 1 | N4: =IF(OR($B4="",$C4="",H4="",I4=""),"",IF(AND(H4=$B4,I4=$C4),INDEX(Parametri!$B:$B,MATCH("Punti Risultato Esatto",Parametri!$A:$A,0)),IF(SIGN($B4-$C4)=SIGN(H4-I4),INDEX(Parametri!$B:$B,MATCH("Punti Solo Segno",Parametri!$A:$A,0)),0))+IF(AND(SIGN($B4-$C4)=SIGN(H4-I4),(--(SIGN(D4-E4)=SIGN($B4-$C4))+--(SIGN(F4-G4)=SIGN($B4-$C4))+--(SIGN(H4-I4)=SIGN($B4-$C4))+--(SIGN(J4-K4)=SIGN($B4-$C4)))=1),INDEX(Parametri!$B:$B,MATCH("Punti Bonus Unico",Parametri!$A:$A,0)),0)) -> 1 | O4: =IF(OR($B4="",$C4="",J4="",K4=""),"",IF(AND(J4=$B4,K4=$C4),INDEX(Parametri!$B:$B,MATCH("Punti Risultato Esatto",Parametri!$A:$A,0)),IF(SIGN($B4-$C4)=SIGN(J4-K4),INDEX(Parametri!$B:$B,MATCH("Punti Solo Segno",Parametri!$A:$A,0)),0))+IF(AND(SIGN($B4-$C4)=SIGN(J4-K4),(--(SIGN(D4-E4)=SIGN($B4-$C4))+--(SIGN(F4-G4)=SIGN($B4-$C4))+--(SIGN(H4-I4)=SIGN($B4-$C4))+--(SIGN(J4-K4)=SIGN($B4-$C4)))=1),INDEX(Parametri!$B:$B,MATCH("Punti Bonus Unico",Parametri!$A:$A,0)),0)) -> 1
A5: Genoa-Napoli | B5: 0 | C5: 2 | D5: 1 | E5: 2 | F5: 1 | G5: 2 | H5: 0 | I5: 1 | J5: 1 | K5: 2 | L5: =IF(OR($B5="",$C5="",D5="",E5=""),"",IF(AND(D5=$B5,E5=$C5),INDEX(Parametri!$B:$B,MATCH("Punti Risultato Esatto",Parametri!$A:$A,0)),IF(SIGN($B5-$C5)=SIGN(D5-E5),INDEX(Parametri!$B:$B,MATCH("Punti Solo Segno",Parametri!$A:$A,0)),0))+IF(AND(SIGN($B5-$C5)=SIGN(D5-E5),(--(SIGN(D5-E5)=SIGN($B5-$C5))+--(SIGN(F5-G5)=SIGN($B5-$C5))+--(SIGN(H5-I5)=SIGN($B5-$C5))+--(SIGN(J5-K5)=SIGN($B5-$C5)))=1),INDEX(Parametri!$B:$B,MATCH("Punti Bonus Unico",Parametri!$A:$A,0)),0)) -> 1 | M5: =IF(OR($B5="",$C5="",F5="",G5=""),"",IF(AND(F5=$B5,G5=$C5),INDEX(Parametri!$B:$B,MATCH("Punti Risultato Esatto",Parametri!$A:$A,0)),IF(SIGN($B5-$C5)=SIGN(F5-G5),INDEX(Parametri!$B:$B,MATCH("Punti Solo Segno",Parametri!$A:$A,0)),0))+IF(AND(SIGN($B5-$C5)=SIGN(F5-G5),(--(SIGN(D5-E5)=SIGN($B5-$C5))+--(SIGN(F5-G5)=SIGN($B5-$C5))+--(SIGN(H5-I5)=SIGN($B5-$C5))+--(SIGN(J5-K5)=SIGN($B5-$C5)))=1),INDEX(Parametri!$B:$B,MATCH("Punti Bonus Unico",Parametri!$A:$A,0)),0)) -> 1 | N5: =IF(OR($B5="",$C5="",H5="",I5=""),"",IF(AND(H5=$B5,I5=$C5),INDEX(Parametri!$B:$B,MATCH("Punti Risultato Esatto",Parametri!$A:$A,0)),IF(SIGN($B5-$C5)=SIGN(H5-I5),INDEX(Parametri!$B:$B,MATCH("Punti Solo Segno",Parametri!$A:$A,0)),0))+IF(AND(SIGN($B5-$C5)=SIGN(H5-I5),(--(SIGN(D5-E5)=SIGN($B5-$C5))+--(SIGN(F5-G5)=SIGN($B5-$C5))+--(SIGN(H5-I5)=SIGN($B5-$C5))+--(SIGN(J5-K5)=SIGN($B5-$C5)))=1),INDEX(Parametri!$B:$B,MATCH("Punti Bonus Unico",Parametri!$A:$A,0)),0)) -> 1 | O5: =IF(OR($B5="",$C5="",J5="",K5=""),"",IF(AND(J5=$B5,K5=$C5),INDEX(Parametri!$B:$B,MATCH("Punti Risultato Esatto",Parametri!$A:$A,0)),IF(SIGN($B5-$C5)=SIGN(J5-K5),INDEX(Parametri!$B:$B,MATCH("Punti Solo Segno",Parametri!$A:$A,0)),0))+IF(AND(SIGN($B5-$C5)=SIGN(J5-K5),(--(SIGN(D5-E5)=SIGN($B5-$C5))+--(SIGN(F5-G5)=SIGN($B5-$C5))+--(SIGN(H5-I5)=SIGN($B5-$C5))+--(SIGN(J5-K5)=SIGN($B5-$C5)))=1),INDEX(Parametri!$B:$B,MATCH("Punti Bonus Unico",Parametri!$A:$A,0)),0)) -> 1
A6: Inter-Monza | B6: 4 | C6: 1 | D6: 3 | E6: 0 | F6: 3 | G6: 0 | H6: 3 | I6: 0 | J6: 3 | K6: 0 | L6: =IF(OR($B6="",$C6="",D6="",E6=""),"",IF(AND(D6=$B6,E6=$C6),INDEX(Parametri!$B:$B,MATCH("Punti Risultato Esatto",Parametri!$A:$A,0)),IF(SIGN($B6-$C6)=SIGN(D6-E6),INDEX(Parametri!$B:$B,MATCH("Punti Solo Segno",Parametri!$A:$A,0)),0))+IF(AND(SIGN($B6-$C6)=SIGN(D6-E6),(--(SIGN(D6-E6)=SIGN($B6-$C6))+--(SIGN(F6-G6)=SIGN($B6-$C6))+--(SIGN(H6-I6)=SIGN($B6-$C6))+--(SIGN(J6-K6)=SIGN($B6-$C6)))=1),INDEX(Parametri!$B:$B,MATCH("Punti Bonus Unico",Parametri!$A:$A,0)),0)) -> 1 | M6: =IF(OR($B6="",$C6="",F6="",G6=""),"",IF(AND(F6=$B6,G6=$C6),INDEX(Parametri!$B:$B,MATCH("Punti Risultato Esatto",Parametri!$A:$A,0)),IF(SIGN($B6-$C6)=SIGN(F6-G6),INDEX(Parametri!$B:$B,MATCH("Punti Solo Segno",Parametri!$A:$A,0)),0))+IF(AND(SIGN($B6-$C6)=SIGN(F6-G6),(--(SIGN(D6-E6)=SIGN($B6-$C6))+--(SIGN(F6-G6)=SIGN($B6-$C6))+--(SIGN(H6-I6)=SIGN($B6-$C6))+--(SIGN(J6-K6)=SIGN($B6-$C6)))=1),INDEX(Parametri!$B:$B,MATCH("Punti Bonus Unico",Parametri!$A:$A,0)),0)) -> 1 | N6: =IF(OR($B6="",$C6="",H6="",I6=""),"",IF(AND(H6=$B6,I6=$C6),INDEX(Parametri!$B:$B,MATCH("Punti Risultato Esatto",Parametri!$A:$A,0)),IF(SIGN($B6-$C6)=SIGN(H6-I6),INDEX(Parametri!$B:$B,MATCH("Punti Solo Segno",Parametri!$A:$A,0)),0))+IF(AND(SIGN($B6-$C6)=SIGN(H6-I6),(--(SIGN(D6-E6)=SIGN($B6-$C6))+--(SIGN(F6-G6)=SIGN($B6-$C6))+--(SIGN(H6-I6)=SIGN($B6-$C6))+--(SIGN(J6-K6)=SIGN($B6-$C6)))=1),INDEX(Parametri!$B:$B,MATCH("Punti Bonus Unico",Parametri!$A:$A,0)),0)) -> 1 | O6: =IF(OR($B6="",$C6="",J6="",K6=""),"",IF(AND(J6=$B6,K6=$C6),INDEX(Parametri!$B:$B,MATCH("Punti Risultato Esatto",Parametri!$A:$A,0)),IF(SIGN($B6-$C6)=SIGN(J6-K6),INDEX(Parametri!$B:$B,MATCH("Punti Solo Segno",Parametri!$A:$A,0)),0))+IF(AND(SIGN($B6-$C6)=SIGN(J6-K6),(--(SIGN(D6-E6)=SIGN($B6-$C6))+--(SIGN(F6-G6)=SIGN($B6-$C6))+--(SIGN(H6-I6)=SIGN($B6-$C6))+--(SIGN(J6-K6)=SIGN($B6-$C6)))=1),INDEX(Parametri!$B:$B,MATCH("Punti Bonus Unico",Parametri!$A:$A,0)),0)) -> 1
A7: Parma-Cagliari | B7: 0 | C7: 1 | D7: 0 | E7: 0 | F7: 0 | G7: 0 | H7: 1 | I7: 1 | J7: 0 | K7: 0 | L7: =IF(OR($B7="",$C7="",D7="",E7=""),"",IF(AND(D7=$B7,E7=$C7),INDEX(Parametri!$B:$B,MATCH("Punti Risultato Esatto",Parametri!$A:$A,0)),IF(SIGN($B7-$C7)=SIGN(D7-E7),INDEX(Parametri!$B:$B,MATCH("Punti Solo Segno",Parametri!$A:$A,0)),0))+IF(AND(SIGN($B7-$C7)=SIGN(D7-E7),(--(SIGN(D7-E7)=SIGN($B7-$C7))+--(SIGN(F7-G7)=SIGN($B7-$C7))+--(SIGN(H7-I7)=SIGN($B7-$C7))+--(SIGN(J7-K7)=SIGN($B7-$C7)))=1),INDEX(Parametri!$B:$B,MATCH("Punti Bonus Unico",Parametri!$A:$A,0)),0)) -> 0 | M7: =IF(OR($B7="",$C7="",F7="",G7=""),"",IF(AND(F7=$B7,G7=$C7),INDEX(Parametri!$B:$B,MATCH("Punti Risultato Esatto",Parametri!$A:$A,0)),IF(SIGN($B7-$C7)=SIGN(F7-G7),INDEX(Parametri!$B:$B,MATCH("Punti Solo Segno",Parametri!$A:$A,0)),0))+IF(AND(SIGN($B7-$C7)=SIGN(F7-G7),(--(SIGN(D7-E7)=SIGN($B7-$C7))+--(SIGN(F7-G7)=SIGN($B7-$C7))+--(SIGN(H7-I7)=SIGN($B7-$C7))+--(SIGN(J7-K7)=SIGN($B7-$C7)))=1),INDEX(Parametri!$B:$B,MATCH("Punti Bonus Unico",Parametri!$A:$A,0)),0)) -> 0 | N7: =IF(OR($B7="",$C7="",H7="",I7=""),"",IF(AND(H7=$B7,I7=$C7),INDEX(Parametri!$B:$B,MATCH("Punti Risultato Esatto",Parametri!$A:$A,0)),IF(SIGN($B7-$C7)=SIGN(H7-I7),INDEX(Parametri!$B:$B,MATCH("Punti Solo Segno",Parametri!$A:$A,0)),0))+IF(AND(SIGN($B7-$C7)=SIGN(H7-I7),(--(SIGN(D7-E7)=SIGN($B7-$C7))+--(SIGN(F7-G7)=SIGN($B7-$C7))+--(SIGN(H7-I7)=SIGN($B7-$C7))+--(SIGN(J7-K7)=SIGN($B7-$C7)))=1),INDEX(Parametri!$B:$B,MATCH("Punti Bonus Unico",Parametri!$A:$A,0)),0)) -> 0 | O7: =IF(OR($B7="",$C7="",J7="",K7=""),"",IF(AND(J7=$B7,K7=$C7),INDEX(Parametri!$B:$B,MATCH("Punti Risultato Esatto",Parametri!$A:$A,0)),IF(SIGN($B7-$C7)=SIGN(J7-K7),INDEX(Parametri!$B:$B,MATCH("Punti Solo Segno",Parametri!$A:$A,0)),0))+IF(AND(SIGN($B7-$C7)=SIGN(J7-K7),(--(SIGN(D7-E7)=SIGN($B7-$C7))+--(SIGN(F7-G7)=SIGN($B7-$C7))+--(SIGN(H7-I7)=SIGN($B7-$C7))+--(SIGN(J7-K7)=SIGN($B7-$C7)))=1),INDEX(Parametri!$B:$B,MATCH("Punti Bonus Unico",Parametri!$A:$A,0)),0)) -> 0
A8: Roma-Fiorentina | L8: =IF(OR($B8="",$C8="",D8="",E8=""),"",IF(AND(D8=$B8,E8=$C8),INDEX(Parametri!$B:$B,MATCH("Punti Risultato Esatto",Parametri!$A:$A,0)),IF(SIGN($B8-$C8)=SIGN(D8-E8),INDEX(Parametri!$B:$B,MATCH("Punti Solo Segno",Parametri!$A:$A,0)),0))+IF(AND(SIGN($B8-$C8)=SIGN(D8-E8),(--(SIGN(D8-E8)=SIGN($B8-$C8))+--(SIGN(F8-G8)=SIGN($B8-$C8))+--(SIGN(H9-I9)=SIGN($B8-$C8))+--(SIGN(J8-K8)=SIGN($B8-$C8)))=1),INDEX(Parametri!$B:$B,MATCH("Punti Bonus Unico",Parametri!$A:$A,0)),0)) | M8: =IF(OR($B8="",$C8="",F8="",G8=""),"",IF(AND(F8=$B8,G8=$C8),INDEX(Parametri!$B:$B,MATCH("Punti Risultato Esatto",Parametri!$A:$A,0)),IF(SIGN($B8-$C8)=SIGN(F8-G8),INDEX(Parametri!$B:$B,MATCH("Punti Solo Segno",Parametri!$A:$A,0)),0))+IF(AND(SIGN($B8-$C8)=SIGN(F8-G8),(--(SIGN(D8-E8)=SIGN($B8-$C8))+--(SIGN(F8-G8)=SIGN($B8-$C8))+--(SIGN(H9-I9)=SIGN($B8-$C8))+--(SIGN(J8-K8)=SIGN($B8-$C8)))=1),INDEX(Parametri!$B:$B,MATCH("Punti Bonus Unico",Parametri!$A:$A,0)),0)) | N8: =IF(OR($B8="",$C8="",H8="",I8=""),"",IF(AND(H8=$B8,I8=$C8),INDEX(Parametri!$B:$B,MATCH("Punti Risultato Esatto",Parametri!$A:$A,0)),IF(SIGN($B8-$C8)=SIGN(H8-I8),INDEX(Parametri!$B:$B,MATCH("Punti Solo Segno",Parametri!$A:$A,0)),0))+IF(AND(SIGN($B8-$C8)=SIGN(H8-I8),(--(SIGN(D8-E8)=SIGN($B8-$C8))+--(SIGN(F8-G8)=SIGN($B8-$C8))+--(SIGN(H8-I8)=SIGN($B8-$C8))+--(SIGN(J8-K8)=SIGN($B8-$C8)))=1),INDEX(Parametri!$B:$B,MATCH("Punti Bonus Unico",Parametri!$A:$A,0)),0)) | O8: =IF(OR($B8="",$C8="",J8="",K8=""),"",IF(AND(J8=$B8,K8=$C8),INDEX(Parametri!$B:$B,MATCH("Punti Risultato Esatto",Parametri!$A:$A,0)),IF(SIGN($B8-$C8)=SIGN(J8-K8),INDEX(Parametri!$B:$B,MATCH("Punti Solo Segno",Parametri!$A:$A,0)),0))+IF(AND(SIGN($B8-$C8)=SIGN(J8-K8),(--(SIGN(D8-E8)=SIGN($B8-$C8))+--(SIGN(F8-G8)=SIGN($B8-$C8))+--(SIGN(H9-I9)=SIGN($B8-$C8))+--(SIGN(J8-K8)=SIGN($B8-$C8)))=1),INDEX(Parametri!$B:$B,MATCH("Punti Bonus Unico",Parametri!$A:$A,0)),0))
A9: Torino-Milan | B9: 1 | C9: 2 | D9: 0 | E9: 1 | F9: 0 | G9: 1 | H9: 1 | I9: 3 | J9: 0 | K9: 2 | L9: =IF(OR($B9="",$C9="",D9="",E9=""),"",IF(AND(D9=$B9,E9=$C9),INDEX(Parametri!$B:$B,MATCH("Punti Risultato Esatto",Parametri!$A:$A,0)),IF(SIGN($B9-$C9)=SIGN(D9-E9),INDEX(Parametri!$B:$B,MATCH("Punti Solo Segno",Parametri!$A:$A,0)),0))+IF(AND(SIGN($B9-$C9)=SIGN(D9-E9),(--(SIGN(D9-E9)=SIGN($B9-$C9))+--(SIGN(F9-G9)=SIGN($B9-$C9))+--(SIGN(H10-I10)=SIGN($B9-$C9))+--(SIGN(J9-K9)=SIGN($B9-$C9)))=1),INDEX(Parametri!$B:$B,MATCH("Punti Bonus Unico",Parametri!$A:$A,0)),0)) -> 1 | M9: =IF(OR($B9="",$C9="",F9="",G9=""),"",IF(AND(F9=$B9,G9=$C9),INDEX(Parametri!$B:$B,MATCH("Punti Risultato Esatto",Parametri!$A:$A,0)),IF(SIGN($B9-$C9)=SIGN(F9-G9),INDEX(Parametri!$B:$B,MATCH("Punti Solo Segno",Parametri!$A:$A,0)),0))+IF(AND(SIGN($B9-$C9)=SIGN(F9-G9),(--(SIGN(D9-E9)=SIGN($B9-$C9))+--(SIGN(F9-G9)=SIGN($B9-$C9))+--(SIGN(H10-I10)=SIGN($B9-$C9))+--(SIGN(J9-K9)=SIGN($B9-$C9)))=1),INDEX(Parametri!$B:$B,MATCH("Punti Bonus Unico",Parametri!$A:$A,0)),0)) -> 1 | N9: =IF(OR($B9="",$C9="",H9="",I9=""),"",IF(AND(H9=$B9,I9=$C9),INDEX(Parametri!$B:$B,MATCH("Punti Risultato Esatto",Parametri!$A:$A,0)),IF(SIGN($B9-$C9)=SIGN(H9-I9),INDEX(Parametri!$B:$B,MATCH("Punti Solo Segno",Parametri!$A:$A,0)),0))+IF(AND(SIGN($B9-$C9)=SIGN(H9-I9),(--(SIGN(D9-E9)=SIGN($B9-$C9))+--(SIGN(F9-G9)=SIGN($B9-$C9))+--(SIGN(H9-I9)=SIGN($B9-$C9))+--(SIGN(J9-K9)=SIGN($B9-$C9)))=1),INDEX(Parametri!$B:$B,MATCH("Punti Bonus Unico",Parametri!$A:$A,0)),0)) -> 1 | O9: =IF(OR($B9="",$C9="",J9="",K9=""),"",IF(AND(J9=$B9,K9=$C9),INDEX(Parametri!$B:$B,MATCH("Punti Risultato Esatto",Parametri!$A:$A,0)),IF(SIGN($B9-$C9)=SIGN(J9-K9),INDEX(Parametri!$B:$B,MATCH("Punti Solo Segno",Parametri!$A:$A,0)),0))+IF(AND(SIGN($B9-$C9)=SIGN(J9-K9),(--(SIGN(D9-E9)=SIGN($B9-$C9))+--(SIGN(F9-G9)=SIGN($B9-$C9))+--(SIGN(H10-I10)=SIGN($B9-$C9))+--(SIGN(J9-K9)=SIGN($B9-$C9)))=1),INDEX(Parametri!$B:$B,MATCH("Punti Bonus Unico",Parametri!$A:$A,0)),0)) -> 1
A10: Udinese-Como | B10: 1 | C10: 1 | D10: 0 | E10: 1 | F10: 1 | G10: 1 | H10: 1 | I10: 2 | J10: 1 | K10: 3 | L10: =IF(OR($B10="",$C10="",D10="",E10=""),"",IF(AND(D10=$B10,E10=$C10),INDEX(Parametri!$B:$B,MATCH("Punti Risultato Esatto",Parametri!$A:$A,0)),IF(SIGN($B10-$C10)=SIGN(D10-E10),INDEX(Parametri!$B:$B,MATCH("Punti Solo Segno",Parametri!$A:$A,0)),0))+IF(AND(SIGN($B10-$C10)=SIGN(D10-E10),(--(SIGN(D10-E10)=SIGN($B10-$C10))+--(SIGN(F10-G10)=SIGN($B10-$C10))+--(SIGN(H11-I11)=SIGN($B10-$C10))+--(SIGN(J10-K10)=SIGN($B10-$C10)))=1),INDEX(Parametri!$B:$B,MATCH("Punti Bonus Unico",Parametri!$A:$A,0)),0)) -> 0 | M10: =IF(OR($B10="",$C10="",F10="",G10=""),"",IF(AND(F10=$B10,G10=$C10),INDEX(Parametri!$B:$B,MATCH("Punti Risultato Esatto",Parametri!$A:$A,0)),IF(SIGN($B10-$C10)=SIGN(F10-G10),INDEX(Parametri!$B:$B,MATCH("Punti Solo Segno",Parametri!$A:$A,0)),0))+IF(AND(SIGN($B10-$C10)=SIGN(F10-G10),(--(SIGN(D10-E10)=SIGN($B10-$C10))+--(SIGN(F10-G10)=SIGN($B10-$C10))+--(SIGN(H11-I11)=SIGN($B10-$C10))+--(SIGN(J10-K10)=SIGN($B10-$C10)))=1),INDEX(Parametri!$B:$B,MATCH("Punti Bonus Unico",Parametri!$A:$A,0)),0)) -> 5 | N10: =IF(OR($B10="",$C10="",H10="",I10=""),"",IF(AND(H10=$B10,I10=$C10),INDEX(Parametri!$B:$B,MATCH("Punti Risultato Esatto",Parametri!$A:$A,0)),IF(SIGN($B10-$C10)=SIGN(H10-I10),INDEX(Parametri!$B:$B,MATCH("Punti Solo Segno",Parametri!$A:$A,0)),0))+IF(AND(SIGN($B10-$C10)=SIGN(H10-I10),(--(SIGN(D10-E10)=SIGN($B10-$C10))+--(SIGN(F10-G10)=SIGN($B10-$C10))+--(SIGN(H10-I10)=SIGN($B10-$C10))+--(SIGN(J10-K10)=SIGN($B10-$C10)))=1),INDEX(Parametri!$B:$B,MATCH("Punti Bonus Unico",Parametri!$A:$A,0)),0)) -> 0 | O10: =IF(OR($B10="",$C10="",J10="",K10=""),"",IF(AND(J10=$B10,K10=$C10),INDEX(Parametri!$B:$B,MATCH("Punti Risultato Esatto",Parametri!$A:$A,0)),IF(SIGN($B10-$C10)=SIGN(J10-K10),INDEX(Parametri!$B:$B,MATCH("Punti Solo Segno",Parametri!$A:$A,0)),0))+IF(AND(SIGN($B10-$C10)=SIGN(J10-K10),(--(SIGN(D10-E10)=SIGN($B10-$C10))+--(SIGN(F10-G10)=SIGN($B10-$C10))+--(SIGN(H11-I11)=SIGN($B10-$C10))+--(SIGN(J10-K10)=SIGN($B10-$C10)))=1),INDEX(Parametri!$B:$B,MATCH("Punti Bonus Unico",Parametri!$A:$A,0)),0)) -> 0
A11: Venezia-Lecce | B11: 0 | C11: 2 | D11: 1 | E11: 0 | F11: 1 | G11: 0 | H11: 1 | I11: 0 | J11: 0 | K11: 0 | L11: =IF(OR($B11="",$C11="",D11="",E11=""),"",IF(AND(D11=$B11,E11=$C11),INDEX(Parametri!$B:$B,MATCH("Punti Risultato Esatto",Parametri!$A:$A,0)),IF(SIGN($B11-$C11)=SIGN(D11-E11),INDEX(Parametri!$B:$B,MATCH("Punti Solo Segno",Parametri!$A:$A,0)),0))+IF(AND(SIGN($B11-$C11)=SIGN(D11-E11),(--(SIGN(D11-E11)=SIGN($B11-$C11))+--(SIGN(F11-G11)=SIGN($B11-$C11))+--(SIGN(H12-I12)=SIGN($B11-$C11))+--(SIGN(J11-K11)=SIGN($B11-$C11)))=1),INDEX(Parametri!$B:$B,MATCH("Punti Bonus Unico",Parametri!$A:$A,0)),0)) -> 0 | M11: =IF(OR($B11="",$C11="",F11="",G11=""),"",IF(AND(F11=$B11,G11=$C11),INDEX(Parametri!$B:$B,MATCH("Punti Risultato Esatto",Parametri!$A:$A,0)),IF(SIGN($B11-$C11)=SIGN(F11-G11),INDEX(Parametri!$B:$B,MATCH("Punti Solo Segno",Parametri!$A:$A,0)),0))+IF(AND(SIGN($B11-$C11)=SIGN(F11-G11),(--(SIGN(D11-E11)=SIGN($B11-$C11))+--(SIGN(F11-G11)=SIGN($B11-$C11))+--(SIGN(H12-I12)=SIGN($B11-$C11))+--(SIGN(J11-K11)=SIGN($B11-$C11)))=1),INDEX(Parametri!$B:$B,MATCH("Punti Bonus Unico",Parametri!$A:$A,0)),0)) -> 0 | N11: =IF(OR($B11="",$C11="",H11="",I11=""),"",IF(AND(H11=$B11,I11=$C11),INDEX(Parametri!$B:$B,MATCH("Punti Risultato Esatto",Parametri!$A:$A,0)),IF(SIGN($B11-$C11)=SIGN(H11-I11),INDEX(Parametri!$B:$B,MATCH("Punti Solo Segno",Parametri!$A:$A,0)),0))+IF(AND(SIGN($B11-$C11)=SIGN(H11-I11),(--(SIGN(D11-E11)=SIGN($B11-$C11))+--(SIGN(F11-G11)=SIGN($B11-$C11))+--(SIGN(H11-I11)=SIGN($B11-$C11))+--(SIGN(J11-K11)=SIGN($B11-$C11)))=1),INDEX(Parametri!$B:$B,MATCH("Punti Bonus Unico",Parametri!$A:$A,0)),0)) -> 0 | O11: =IF(OR($B11="",$C11="",J11="",K11=""),"",IF(AND(J11=$B11,K11=$C11),INDEX(Parametri!$B:$B,MATCH("Punti Risultato Esatto",Parametri!$A:$A,0)),IF(SIGN($B11-$C11)=SIGN(J11-K11),INDEX(Parametri!$B:$B,MATCH("Punti Solo Segno",Parametri!$A:$A,0)),0))+IF(AND(SIGN($B11-$C11)=SIGN(J11-K11),(--(SIGN(D11-E11)=SIGN($B11-$C11))+--(SIGN(F11-G11)=SIGN($B11-$C11))+--(SIGN(H12-I12)=SIGN($B11-$C11))+--(SIGN(J11-K11)=SIGN($B11-$C11)))=1),INDEX(Parametri!$B:$B,MATCH("Punti Bonus Unico",Parametri!$A:$A,0)),0)) -> 0
A12: Totale giornata | L12: =SUM(L2:L11) -> 5 | M12: =SUM(M2:M11) -> 13 | N12: =SUM(N2:N11) -> 6 | O12: =SUM(O2:O11) -> 4

Sheet Giornata 2
A1: Partita | B1: Gol Casa Reale | C1: Gol Ospite Reale | D1: Ale Casa | E1: Ale Ospite | F1: Dani Casa | G1: Dani Ospite | H1: Dipa Casa | I1: Dipa Ospite | J1: Mando Casa | K1: Mando Ospite | L1: Punti Ale | M1: Punti Dani | N1: Punti Dipa | O1: Punti Mando
A2: Atalanta-Bologna | B2: 1 | C2: 0 | D2: 2 | E2: 0 | F2: 1 | G2: 1 | H2: 2 | I2: 1 | J2: 1 | K2: 0 | L2: =IF(OR($B2="",$C2="",D2="",E2=""),"",IF(AND(D2=$B2,E2=$C2),INDEX(Parametri!$B:$B,MATCH("Punti Risultato Esatto",Parametri!$A:$A,0)),IF(SIGN($B2-$C2)=SIGN(D2-E2),INDEX(Parametri!$B:$B,MATCH("Punti Solo Segno",Parametri!$A:$A,0)),0))+IF(AND(SIGN($B2-$C2)=SIGN(D2-E2),(--(SIGN(D2-E2)=SIGN($B2-$C2))+--(SIGN(F2-G2)=SIGN($B2-$C2))+--(SIGN(H2-I2)=SIGN($B2-$C2))+--(SIGN(J2-K2)=SIGN($B2-$C2)))=1),INDEX(Parametri!$B:$B,MATCH("Punti Bonus Unico",Parametri!$A:$A,0)),0)) -> 1 | M2: =IF(OR($B2="",$C2="",F2="",G2=""),"",IF(AND(F2=$B2,G2=$C2),INDEX(Parametri!$B:$B,MATCH("Punti Risultato Esatto",Parametri!$A:$A,0)),IF(SIGN($B2-$C2)=SIGN(F2-G2),INDEX(Parametri!$B:$B,MATCH("Punti Solo Segno",Parametri!$A:$A,0)),0))+IF(AND(SIGN($B2-$C2)=SIGN(F2-G2),(--(SIGN(D2-E2)=SIGN($B2-$C2))+--(SIGN(F2-G2)=SIGN($B2-$C2))+--(SIGN(H2-I2)=SIGN($B2-$C2))+--(SIGN(J2-K2)=SIGN($B2-$C2)))=1),INDEX(Parametri!$B:$B,MATCH("Punti Bonus Unico",Parametri!$A:$A,0)),0)) -> 0 | N2: =IF(OR($B2="",$C2="",H2="",I2=""),"",IF(AND(H2=$B2,I2=$C2),INDEX(Parametri!$B:$B,MATCH("Punti Risultato Esatto",Parametri!$A:$A,0)),IF(SIGN($B2-$C2)=SIGN(H2-I2),INDEX(Parametri!$B:$B,MATCH("Punti Solo Segno",Parametri!$A:$A,0)),0))+IF(AND(SIGN($B2-$C2)=SIGN(H2-I2),(--(SIGN(D2-E2)=SIGN($B2-$C2))+--(SIGN(F2-G2)=SIGN($B2-$C2))+--(SIGN(H2-I2)=SIGN($B2-$C2))+--(SIGN(J2-K2)=SIGN($B2-$C2)))=1),INDEX(Parametri!$B:$B,MATCH("Punti Bonus Unico",Parametri!$A:$A,0)),0)) -> 1 | O2: =IF(OR($B2="",$C2="",J2="",K2=""),"",IF(AND(J2=$B2,K2=$C2),INDEX(Parametri!$B:$B,MATCH("Punti Risultato Esatto",Parametri!$A:$A,0)),IF(SIGN($B2-$C2)=SIGN(J2-K2),INDEX(Parametri!$B:$B,MATCH("Punti Solo Segno",Parametri!$A:$A,0)),0))+IF(AND(SIGN($B2-$C2)=SIGN(J2-K2),(--(SIGN(D2-E2)=SIGN($B2-$C2))+--(SIGN(F2-G2)=SIGN($B2-$C2))+--(SIGN(H2-I2)=SIGN($B2-$C2))+--(SIGN(J2-K2)=SIGN($B2-$C2)))=1),INDEX(Parametri!$B:$B,MATCH("Punti Bonus Unico",Parametri!$A:$A,0)),0)) -> 2
A3: Cagliari-Inter | B3: 0 | C3: 1 | D3: 1 | E3: 2 | F3: 0 | G3: 2 | H3: 0 | I3: 2 | J3: 0 | K3: 2 | L3: =IF(OR($B3="",$C3="",D3="",E3=""),"",IF(AND(D3=$B3,E3=$C3),INDEX(Parametri!$B:$B,MATCH("Punti Risultato Esatto",Parametri!$A:$A,0)),IF(SIGN($B3-$C3)=SIGN(D3-E3),INDEX(Parametri!$B:$B,MATCH("Punti Solo Segno",Parametri!$A:$A,0)),0))+IF(AND(SIGN($B3-$C3)=SIGN(D3-E3),(--(SIGN(D3-E3)=SIGN($B3-$C3))+--(SIGN(F3-G3)=SIGN($B3-$C3))+--(SIGN(H3-I3)=SIGN($B3-$C3))+--(SIGN(J3-K3)=SIGN($B3-$C3)))=1),INDEX(Parametri!$B:$B,MATCH("Punti Bonus Unico",Parametri!$A:$A,0)),0)) -> 1 | M3: =IF(OR($B3="",$C3="",F3="",G3=""),"",IF(AND(F3=$B3,G3=$C3),INDEX(Parametri!$B:$B,MATCH("Punti Risultato Esatto",Parametri!$A:$A,0)),IF(SIGN($B3-$C3)=SIGN(F3-G3),INDEX(Parametri!$B:$B,MATCH("Punti Solo Segno",Parametri!$A:$A,0)),0))+IF(AND(SIGN($B3-$C3)=SIGN(F3-G3),(--(SIGN(D3-E3)=SIGN($B3-$C3))+--(SIGN(F3-G3)=SIGN($B3-$C3))+--(SIGN(H3-I3)=SIGN($B3-$C3))+--(SIGN(J3-K3)=SIGN($B3-$C3)))=1),INDEX(Parametri!$B:$B,MATCH("Punti Bonus Unico",Parametri!$A:$A,0)),0)) -> 1 | N3: =IF(OR($B3="",$C3="",H3="",I3=""),"",IF(AND(H3=$B3,I3=$C3),INDEX(Parametri!$B:$B,MATCH("Punti Risultato Esatto",Parametri!$A:$A,0)),IF(SIGN($B3-$C3)=SIGN(H3-I3),INDEX(Parametri!$B:$B,MATCH("Punti Solo Segno",Parametri!$A:$A,0)),0))+IF(AND(SIGN($B3-$C3)=SIGN(H3-I3),(--(SIGN(D3-E3)=SIGN($B3-$C3))+--(SIGN(F3-G3)=SIGN($B3-$C3))+--(SIGN(H3-I3)=SIGN($B3-$C3))+--(SIGN(J3-K3)=SIGN($B3-$C3)))=1),INDEX(Parametri!$B:$B,MATCH("Punti Bonus Unico",Parametri!$A:$A,0)),0)) -> 1 | O3: =IF(OR($B3="",$C3="",J3="",K3=""),"",IF(AND(J3=$B3,K3=$C3),INDEX(Parametri!$B:$B,MATCH("Punti Risultato Esatto",Parametri!$A:$A,0)),IF(SIGN($B3-$C3)=SIGN(J3-K3),INDEX(Parametri!$B:$B,MATCH("Punti Solo Segno",Parametri!$A:$A,0)),0))+IF(AND(SIGN($B3-$C3)=SIGN(J3-K3),(--(SIGN(D3-E3)=SIGN($B3-$C3))+--(SIGN(F3-G3)=SIGN($B3-$C3))+--(SIGN(H3-I3)=SIGN($B3-$C3))+--(SIGN(J3-K3)=SIGN($B3-$C3)))=1),INDEX(Parametri!$B:$B,MATCH("Punti Bonus Unico",Parametri!$A:$A,0)),0)) -> 1
A4: Fiorentina-Frosinone | B4: 0 | C4: 3 | D4: 2 | E4: 0 | F4: 2 | G4: 1 | H4: 2 | I4: 0 | J4: 2 | K4: 0 | L4: =IF(OR($B4="",$C4="",D4="",E4=""),"",IF(AND(D4=$B4,E4=$C4),INDEX(Parametri!$B:$B,MATCH("Punti Risultato Esatto",Parametri!$A:$A,0)),IF(SIGN($B4-$C4)=SIGN(D4-E4),INDEX(Parametri!$B:$B,MATCH("Punti Solo Segno",Parametri!$A:$A,0)),0))+IF(AND(SIGN($B4-$C4)=SIGN(D4-E4),(--(SIGN(D4-E4)=SIGN($B4-$C4))+--(SIGN(F4-G4)=SIGN($B4-$C4))+--(SIGN(H4-I4)=SIGN($B4-$C4))+--(SIGN(J4-K4)=SIGN($B4-$C4)))=1),INDEX(Parametri!$B:$B,MATCH("Punti Bonus Unico",Parametri!$A:$A,0)),0)) -> 0 | M4: =IF(OR($B4="",$C4="",F4="",G4=""),"",IF(AND(F4=$B4,G4=$C4),INDEX(Parametri!$B:$B,MATCH("Punti Risultato Esatto",Parametri!$A:$A,0)),IF(SIGN($B4-$C4)=SIGN(F4-G4),INDEX(Parametri!$B:$B,MATCH("Punti Solo Segno",Parametri!$A:$A,0)),0))+IF(AND(SIGN($B4-$C4)=SIGN(F4-G4),(--(SIGN(D4-E4)=SIGN($B4-$C4))+--(SIGN(F4-G4)=SIGN($B4-$C4))+--(SIGN(H4-I4)=SIGN($B4-$C4))+--(SIGN(J4-K4)=SIGN($B4-$C4)))=1),INDEX(Parametri!$B:$B,MATCH("Punti Bonus Unico",Parametri!$A:$A,0)),0)) -> 0 | N4: =IF(OR($B4="",$C4="",H4="",I4=""),"",IF(AND(H4=$B4,I4=$C4),INDEX(Parametri!$B:$B,MATCH("Punti Risultato Esatto",Parametri!$A:$A,0)),IF(SIGN($B4-$C4)=SIGN(H4-I4),INDEX(Parametri!$B:$B,MATCH("Punti Solo Segno",Parametri!$A:$A,0)),0))+IF(AND(SIGN($B4-$C4)=SIGN(H4-I4),(--(SIGN(D4-E4)=SIGN($B4-$C4))+--(SIGN(F4-G4)=SIGN($B4-$C4))+--(SIGN(H4-I4)=SIGN($B4-$C4))+--(SIGN(J4-K4)=SIGN($B4-$C4)))=1),INDEX(Parametri!$B:$B,MATCH("Punti Bonus Unico",Parametri!$A:$A,0)),0)) -> 0 | O4: =IF(OR($B4="",$C4="",J4="",K4=""),"",IF(AND(J4=$B4,K4=$C4),INDEX(Parametri!$B:$B,MATCH("Punti Risultato Esatto",Parametri!$A:$A,0)),IF(SIGN($B4-$C4)=SIGN(J4-K4),INDEX(Parametri!$B:$B,MATCH("Punti Solo Segno",Parametri!$A:$A,0)),0))+IF(AND(SIGN($B4-$C4)=SIGN(J4-K4),(--(SIGN(D4-E4)=SIGN($B4-$C4))+--(SIGN(F4-G4)=SIGN($B4-$C4))+--(SIGN(H4-I4)=SIGN($B4-$C4))+--(SIGN(J4-K4)=SIGN($B4-$C4)))=1),INDEX(Parametri!$B:$B,MATCH("Punti Bonus Unico",Parametri!$A:$A,0)),0)) -> 0
A5: Juventus-Parma | B5: 2 | C5: 0 | D5: 2 | E5: 0 | F5: 1 | G5: 0 | H5: 3 | I5: 0 | J5: 2 | K5: 0 | L5: =IF(OR($B5="",$C5="",D5="",E5=""),"",IF(AND(D5=$B5,E5=$C5),INDEX(Parametri!$B:$B,MATCH("Punti Risultato Esatto",Parametri!$A:$A,0)),IF(SIGN($B5-$C5)=SIGN(D5-E5),INDEX(Parametri!$B:$B,MATCH("Punti Solo Segno",Parametri!$A:$A,0)),0))+IF(AND(SIGN($B5-$C5)=SIGN(D5-E5),(--(SIGN(D5-E5)=SIGN($B5-$C5))+--(SIGN(F5-G5)=SIGN($B5-$C5))+--(SIGN(H5-I5)=SIGN($B5-$C5))+--(SIGN(J5-K5)=SIGN($B5-$C5)))=1),INDEX(Parametri!$B:$B,MATCH("Punti Bonus Unico",Parametri!$A:$A,0)),0)) -> 2 | M5: =IF(OR($B5="",$C5="",F5="",G5=""),"",IF(AND(F5=$B5,G5=$C5),INDEX(Parametri!$B:$B,MATCH("Punti Risultato Esatto",Parametri!$A:$A,0)),IF(SIGN($B5-$C5)=SIGN(F5-G5),INDEX(Parametri!$B:$B,MATCH("Punti Solo Segno",Parametri!$A:$A,0)),0))+IF(AND(SIGN($B5-$C5)=SIGN(F5-G5),(--(SIGN(D5-E5)=SIGN($B5-$C5))+--(SIGN(F5-G5)=SIGN($B5-$C5))+--(SIGN(H5-I5)=SIGN($B5-$C5))+--(SIGN(J5-K5)=SIGN($B5-$C5)))=1),INDEX(Parametri!$B:$B,MATCH("Punti Bonus Unico",Parametri!$A:$A,0)),0)) -> 1 | N5: =IF(OR($B5="",$C5="",H5="",I5=""),"",IF(AND(H5=$B5,I5=$C5),INDEX(Parametri!$B:$B,MATCH("Punti Risultato Esatto",Parametri!$A:$A,0)),IF(SIGN($B5-$C5)=SIGN(H5-I5),INDEX(Parametri!$B:$B,MATCH("Punti Solo Segno",Parametri!$A:$A,0)),0))+IF(AND(SIGN($B5-$C5)=SIGN(H5-I5),(--(SIGN(D5-E5)=SIGN($B5-$C5))+--(SIGN(F5-G5)=SIGN($B5-$C5))+--(SIGN(H5-I5)=SIGN($B5-$C5))+--(SIGN(J5-K5)=SIGN($B5-$C5)))=1),INDEX(Parametri!$B:$B,MATCH("Punti Bonus Unico",Parametri!$A:$A,0)),0)) -> 1 | O5: =IF(OR($B5="",$C5="",J5="",K5=""),"",IF(AND(J5=$B5,K5=$C5),INDEX(Parametri!$B:$B,MATCH("Punti Risultato Esatto",Parametri!$A:$A,0)),IF(SIGN($B5-$C5)=SIGN(J5-K5),INDEX(Parametri!$B:$B,MATCH("Punti Solo Segno",Parametri!$A:$A,0)),0))+IF(AND(SIGN($B5-$C5)=SIGN(J5-K5),(--(SIGN(D5-E5)=SIGN($B5-$C5))+--(SIGN(F5-G5)=SIGN($B5-$C5))+--(SIGN(H5-I5)=SIGN($B5-$C5))+--(SIGN(J5-K5)=SIGN($B5-$C5)))=1),INDEX(Parametri!$B:$B,MATCH("Punti Bonus Unico",Parametri!$A:$A,0)),0)) -> 2
A6: Lazio-Genoa | B6: 1 | C6: 0 | D6: 1 | E6: 1 | F6: 1 | G6: 1 | H6: 1 | I6: 1 | J6: 1 | K6: 1 | L6: =IF(OR($B6="",$C6="",D6="",E6=""),"",IF(AND(D6=$B6,E6=$C6),INDEX(Parametri!$B:$B,MATCH("Punti Risultato Esatto",Parametri!$A:$A,0)),IF(SIGN($B6-$C6)=SIGN(D6-E6),INDEX(Parametri!$B:$B,MATCH("Punti Solo Segno",Parametri!$A:$A,0)),0))+IF(AND(SIGN($B6-$C6)=SIGN(D6-E6),(--(SIGN(D6-E6)=SIGN($B6-$C6))+--(SIGN(F6-G6)=SIGN($B6-$C6))+--(SIGN(H6-I6)=SIGN($B6-$C6))+--(SIGN(J6-K6)=SIGN($B6-$C6)))=1),INDEX(Parametri!$B:$B,MATCH("Punti Bonus Unico",Parametri!$A:$A,0)),0)) -> 0 | M6: =IF(OR($B6="",$C6="",F6="",G6=""),"",IF(AND(F6=$B6,G6=$C6),INDEX(Parametri!$B:$B,MATCH("Punti Risultato Esatto",Parametri!$A:$A,0)),IF(SIGN($B6-$C6)=SIGN(F6-G6),INDEX(Parametri!$B:$B,MATCH("Punti Solo Segno",Parametri!$A:$A,0)),0))+IF(AND(SIGN($B6-$C6)=SIGN(F6-G6),(--(SIGN(D6-E6)=SIGN($B6-$C6))+--(SIGN(F6-G6)=SIGN($B6-$C6))+--(SIGN(H6-I6)=SIGN($B6-$C6))+--(SIGN(J6-K6)=SIGN($B6-$C6)))=1),INDEX(Parametri!$B:$B,MATCH("Punti Bonus Unico",Parametri!$A:$A,0)),0)) -> 0 | N6: =IF(OR($B6="",$C6="",H6="",I6=""),"",IF(AND(H6=$B6,I6=$C6),INDEX(Parametri!$B:$B,MATCH("Punti Risultato Esatto",Parametri!$A:$A,0)),IF(SIGN($B6-$C6)=SIGN(H6-I6),INDEX(Parametri!$B:$B,MATCH("Punti Solo Segno",Parametri!$A:$A,0)),0))+IF(AND(SIGN($B6-$C6)=SIGN(H6-I6),(--(SIGN(D6-E6)=SIGN($B6-$C6))+--(SIGN(F6-G6)=SIGN($B6-$C6))+--(SIGN(H6-I6)=SIGN($B6-$C6))+--(SIGN(J6-K6)=SIGN($B6-$C6)))=1),INDEX(Parametri!$B:$B,MATCH("Punti Bonus Unico",Parametri!$A:$A,0)),0)) -> 0 | O6: =IF(OR($B6="",$C6="",J6="",K6=""),"",IF(AND(J6=$B6,K6=$C6),INDEX(Parametri!$B:$B,MATCH("Punti Risultato Esatto",Parametri!$A:$A,0)),IF(SIGN($B6-$C6)=SIGN(J6-K6),INDEX(Parametri!$B:$B,MATCH("Punti Solo Segno",Parametri!$A:$A,0)),0))+IF(AND(SIGN($B6-$C6)=SIGN(J6-K6),(--(SIGN(D6-E6)=SIGN($B6-$C6))+--(SIGN(F6-G6)=SIGN($B6-$C6))+--(SIGN(H6-I6)=SIGN($B6-$C6))+--(SIGN(J6-K6)=SIGN($B6-$C6)))=1),INDEX(Parametri!$B:$B,MATCH("Punti Bonus Unico",Parametri!$A:$A,0)),0)) -> 0
A7: Lecce-Roma | L7: =IF(OR($B7="",$C7="",D7="",E7=""),"",IF(AND(D7=$B7,E7=$C7),INDEX(Parametri!$B:$B,MATCH("Punti Risultato Esatto",Parametri!$A:$A,0)),IF(SIGN($B7-$C7)=SIGN(D7-E7),INDEX(Parametri!$B:$B,MATCH("Punti Solo Segno",Parametri!$A:$A,0)),0))+IF(AND(SIGN($B7-$C7)=SIGN(D7-E7),(--(SIGN(D7-E7)=SIGN($B7-$C7))+--(SIGN(F7-G7)=SIGN($B7-$C7))+--(SIGN(H7-I7)=SIGN($B7-$C7))+--(SIGN(J7-K7)=SIGN($B7-$C7)))=1),INDEX(Parametri!$B:$B,MATCH("Punti Bonus Unico",Parametri!$A:$A,0)),0)) | M7: =IF(OR($B7="",$C7="",F7="",G7=""),"",IF(AND(F7=$B7,G7=$C7),INDEX(Parametri!$B:$B,MATCH("Punti Risultato Esatto",Parametri!$A:$A,0)),IF(SIGN($B7-$C7)=SIGN(F7-G7),INDEX(Parametri!$B:$B,MATCH("Punti Solo Segno",Parametri!$A:$A,0)),0))+IF(AND(SIGN($B7-$C7)=SIGN(F7-G7),(--(SIGN(D7-E7)=SIGN($B7-$C7))+--(SIGN(F7-G7)=SIGN($B7-$C7))+--(SIGN(H7-I7)=SIGN($B7-$C7))+--(SIGN(J7-K7)=SIGN($B7-$C7)))=1),INDEX(Parametri!$B:$B,MATCH("Punti Bonus Unico",Parametri!$A:$A,0)),0)) | N7: =IF(OR($B7="",$C7="",H7="",I7=""),"",IF(AND(H7=$B7,I7=$C7),INDEX(Parametri!$B:$B,MATCH("Punti Risultato Esatto",Parametri!$A:$A,0)),IF(SIGN($B7-$C7)=SIGN(H7-I7),INDEX(Parametri!$B:$B,MATCH("Punti Solo Segno",Parametri!$A:$A,0)),0))+IF(AND(SIGN($B7-$C7)=SIGN(H7-I7),(--(SIGN(D7-E7)=SIGN($B7-$C7))+--(SIGN(F7-G7)=SIGN($B7-$C7))+--(SIGN(H7-I7)=SIGN($B7-$C7))+--(SIGN(J7-K7)=SIGN($B7-$C7)))=1),INDEX(Parametri!$B:$B,MATCH("Punti Bonus Unico",Parametri!$A:$A,0)),0)) | O7: =IF(OR($B7="",$C7="",J7="",K7=""),"",IF(AND(J7=$B7,K7=$C7),INDEX(Parametri!$B:$B,MATCH("Punti Risultato Esatto",Parametri!$A:$A,0)),IF(SIGN($B7-$C7)=SIGN(J7-K7),INDEX(Parametri!$B:$B,MATCH("Punti Solo Segno",Parametri!$A:$A,0)),0))+IF(AND(SIGN($B7-$C7)=SIGN(J7-K7),(--(SIGN(D7-E7)=SIGN($B7-$C7))+--(SIGN(F7-G7)=SIGN($B7-$C7))+--(SIGN(H7-I7)=SIGN($B7-$C7))+--(SIGN(J7-K7)=SIGN($B7-$C7)))=1),INDEX(Parametri!$B:$B,MATCH("Punti Bonus Unico",Parametri!$A:$A,0)),0))
A8: Milan-Venezia | B8: 2 | C8: 0 | D8: 2 | E8: 0 | F8: 2 | G8: 0 | H8: 3 | I8: 1 | J8: 3 | K8: 0 | L8: =IF(OR($B8="",$C8="",D8="",E8=""),"",IF(AND(D8=$B8,E8=$C8),INDEX(Parametri!$B:$B,MATCH("Punti Risultato Esatto",Parametri!$A:$A,0)),IF(SIGN($B8-$C8)=SIGN(D8-E8),INDEX(Parametri!$B:$B,MATCH("Punti Solo Segno",Parametri!$A:$A,0)),0))+IF(AND(SIGN($B8-$C8)=SIGN(D8-E8),(--(SIGN(D8-E8)=SIGN($B8-$C8))+--(SIGN(F8-G8)=SIGN($B8-$C8))+--(SIGN(H8-I8)=SIGN($B8-$C8))+--(SIGN(J8-K8)=SIGN($B8-$C8)))=1),INDEX(Parametri!$B:$B,MATCH("Punti Bonus Unico",Parametri!$A:$A,0)),0)) -> 2 | M8: =IF(OR($B8="",$C8="",F8="",G8=""),"",IF(AND(F8=$B8,G8=$C8),INDEX(Parametri!$B:$B,MATCH("Punti Risultato Esatto",Parametri!$A:$A,0)),IF(SIGN($B8-$C8)=SIGN(F8-G8),INDEX(Parametri!$B:$B,MATCH("Punti Solo Segno",Parametri!$A:$A,0)),0))+IF(AND(SIGN($B8-$C8)=SIGN(F8-G8),(--(SIGN(D8-E8)=SIGN($B8-$C8))+--(SIGN(F8-G8)=SIGN($B8-$C8))+--(SIGN(H8-I8)=SIGN($B8-$C8))+--(SIGN(J8-K8)=SIGN($B8-$C8)))=1),INDEX(Parametri!$B:$B,MATCH("Punti Bonus Unico",Parametri!$A:$A,0)),0)) -> 2 | N8: =IF(OR($B8="",$C8="",H8="",I8=""),"",IF(AND(H8=$B8,I8=$C8),INDEX(Parametri!$B:$B,MATCH("Punti Risultato Esatto",Parametri!$A:$A,0)),IF(SIGN($B8-$C8)=SIGN(H8-I8),INDEX(Parametri!$B:$B,MATCH("Punti Solo Segno",Parametri!$A:$A,0)),0))+IF(AND(SIGN($B8-$C8)=SIGN(H8-I8),(--(SIGN(D8-E8)=SIGN($B8-$C8))+--(SIGN(F8-G8)=SIGN($B8-$C8))+--(SIGN(H8-I8)=SIGN($B8-$C8))+--(SIGN(J8-K8)=SIGN($B8-$C8)))=1),INDEX(Parametri!$B:$B,MATCH("Punti Bonus Unico",Parametri!$A:$A,0)),0)) -> 1 | O8: =IF(OR($B8="",$C8="",J8="",K8=""),"",IF(AND(J8=$B8,K8=$C8),INDEX(Parametri!$B:$B,MATCH("Punti Risultato Esatto",Parametri!$A:$A,0)),IF(SIGN($B8-$C8)=SIGN(J8-K8),INDEX(Parametri!$B:$B,MATCH("Punti Solo Segno",Parametri!$A:$A,0)),0))+IF(AND(SIGN($B8-$C8)=SIGN(J8-K8),(--(SIGN(D8-E8)=SIGN($B8-$C8))+--(SIGN(F8-G8)=SIGN($B8-$C8))+--(SIGN(H8-I8)=SIGN($B8-$C8))+--(SIGN(J8-K8)=SIGN($B8-$C8)))=1),INDEX(Parametri!$B:$B,MATCH("Punti Bonus Unico",Parametri!$A:$A,0)),0)) -> 1
A9: Monza-Udinese | B9: 2 | C9: 3 | D9: 0 | E9: 1 | F9: 1 | G9: 2 | H9: 1 | I9: 2 | J9: 1 | K9: 2 | L9: =IF(OR($B9="",$C9="",D9="",E9=""),"",IF(AND(D9=$B9,E9=$C9),INDEX(Parametri!$B:$B,MATCH("Punti Risultato Esatto",Parametri!$A:$A,0)),IF(SIGN($B9-$C9)=SIGN(D9-E9),INDEX(Parametri!$B:$B,MATCH("Punti Solo Segno",Parametri!$A:$A,0)),0))+IF(AND(SIGN($B9-$C9)=SIGN(D9-E9),(--(SIGN(D9-E9)=SIGN($B9-$C9))+--(SIGN(F9-G9)=SIGN($B9-$C9))+--(SIGN(H9-I9)=SIGN($B9-$C9))+--(SIGN(J9-K9)=SIGN($B9-$C9)))=1),INDEX(Parametri!$B:$B,MATCH("Punti Bonus Unico",Parametri!$A:$A,0)),0)) -> 1 | M9: =IF(OR($B9="",$C9="",F9="",G9=""),"",IF(AND(F9=$B9,G9=$C9),INDEX(Parametri!$B:$B,MATCH("Punti Risultato Esatto",Parametri!$A:$A,0)),IF(SIGN($B9-$C9)=SIGN(F9-G9),INDEX(Parametri!$B:$B,MATCH("Punti Solo Segno",Parametri!$A:$A,0)),0))+IF(AND(SIGN($B9-$C9)=SIGN(F9-G9),(--(SIGN(D9-E9)=SIGN($B9-$C9))+--(SIGN(F9-G9)=SIGN($B9-$C9))+--(SIGN(H9-I9)=SIGN($B9-$C9))+--(SIGN(J9-K9)=SIGN($B9-$C9)))=1),INDEX(Parametri!$B:$B,MATCH("Punti Bonus Unico",Parametri!$A:$A,0)),0)) -> 1 | N9: =IF(OR($B9="",$C9="",H9="",I9=""),"",IF(AND(H9=$B9,I9=$C9),INDEX(Parametri!$B:$B,MATCH("Punti Risultato Esatto",Parametri!$A:$A,0)),IF(SIGN($B9-$C9)=SIGN(H9-I9),INDEX(Parametri!$B:$B,MATCH("Punti Solo Segno",Parametri!$A:$A,0)),0))+IF(AND(SIGN($B9-$C9)=SIGN(H9-I9),(--(SIGN(D9-E9)=SIGN($B9-$C9))+--(SIGN(F9-G9)=SIGN($B9-$C9))+--(SIGN(H9-I9)=SIGN($B9-$C9))+--(SIGN(J9-K9)=SIGN($B9-$C9)))=1),INDEX(Parametri!$B:$B,MATCH("Punti Bonus Unico",Parametri!$A:$A,0)),0)) -> 1 | O9: =IF(OR($B9="",$C9="",J9="",K9=""),"",IF(AND(J9=$B9,K9=$C9),INDEX(Parametri!$B:$B,MATCH("Punti Risultato Esatto",Parametri!$A:$A,0)),IF(SIGN($B9-$C9)=SIGN(J9-K9),INDEX(Parametri!$B:$B,MATCH("Punti Solo Segno",Parametri!$A:$A,0)),0))+IF(AND(SIGN($B9-$C9)=SIGN(J9-K9),(--(SIGN(D9-E9)=SIGN($B9-$C9))+--(SIGN(F9-G9)=SIGN($B9-$C9))+--(SIGN(H9-I9)=SIGN($B9-$C9))+--(SIGN(J9-K9)=SIGN($B9-$C9)))=1),INDEX(Parametri!$B:$B,MATCH("Punti Bonus Unico",Parametri!$A:$A,0)),0)) -> 1
A10: Napoli-Como | B10: 1 | C10: 2 | D10: 1 | E10: 1 | F10: 1 | G10: 1 | H10: 2 | I10: 2 | J10: 0 | K10: 0 | L10: =IF(OR($B10="",$C10="",D10="",E10=""),"",IF(AND(D10=$B10,E10=$C10),INDEX(Parametri!$B:$B,MATCH("Punti Risultato Esatto",Parametri!$A:$A,0)),IF(SIGN($B10-$C10)=SIGN(D10-E10),INDEX(Parametri!$B:$B,MATCH("Punti Solo Segno",Parametri!$A:$A,0)),0))+IF(AND(SIGN($B10-$C10)=SIGN(D10-E10),(--(SIGN(D10-E10)=SIGN($B10-$C10))+--(SIGN(F10-G10)=SIGN($B10-$C10))+--(SIGN(H10-I10)=SIGN($B10-$C10))+--(SIGN(J10-K10)=SIGN($B10-$C10)))=1),INDEX(Parametri!$B:$B,MATCH("Punti Bonus Unico",Parametri!$A:$A,0)),0)) -> 0 | M10: =IF(OR($B10="",$C10="",F10="",G10=""),"",IF(AND(F10=$B10,G10=$C10),INDEX(Parametri!$B:$B,MATCH("Punti Risultato Esatto",Parametri!$A:$A,0)),IF(SIGN($B10-$C10)=SIGN(F10-G10),INDEX(Parametri!$B:$B,MATCH("Punti Solo Segno",Parametri!$A:$A,0)),0))+IF(AND(SIGN($B10-$C10)=SIGN(F10-G10),(--(SIGN(D10-E10)=SIGN($B10-$C10))+--(SIGN(F10-G10)=SIGN($B10-$C10))+--(SIGN(H10-I10)=SIGN($B10-$C10))+--(SIGN(J10-K10)=SIGN($B10-$C10)))=1),INDEX(Parametri!$B:$B,MATCH("Punti Bonus Unico",Parametri!$A:$A,0)),0)) -> 0 | N10: =IF(OR($B10="",$C10="",H10="",I10=""),"",IF(AND(H10=$B10,I10=$C10),INDEX(Parametri!$B:$B,MATCH("Punti Risultato Esatto",Parametri!$A:$A,0)),IF(SIGN($B10-$C10)=SIGN(H10-I10),INDEX(Parametri!$B:$B,MATCH("Punti Solo Segno",Parametri!$A:$A,0)),0))+IF(AND(SIGN($B10-$C10)=SIGN(H10-I10),(--(SIGN(D10-E10)=SIGN($B10-$C10))+--(SIGN(F10-G10)=SIGN($B10-$C10))+--(SIGN(H10-I10)=SIGN($B10-$C10))+--(SIGN(J10-K10)=SIGN($B10-$C10)))=1),INDEX(Parametri!$B:$B,MATCH("Punti Bonus Unico",Parametri!$A:$A,0)),0)) -> 0 | O10: =IF(OR($B10="",$C10="",J10="",K10=""),"",IF(AND(J10=$B10,K10=$C10),INDEX(Parametri!$B:$B,MATCH("Punti Risultato Esatto",Parametri!$A:$A,0)),IF(SIGN($B10-$C10)=SIGN(J10-K10),INDEX(Parametri!$B:$B,MATCH("Punti Solo Segno",Parametri!$A:$A,0)),0))+IF(AND(SIGN($B10-$C10)=SIGN(J10-K10),(--(SIGN(D10-E10)=SIGN($B10-$C10))+--(SIGN(F10-G10)=SIGN($B10-$C10))+--(SIGN(H10-I10)=SIGN($B10-$C10))+--(SIGN(J10-K10)=SIGN($B10-$C10)))=1),INDEX(Parametri!$B:$B,MATCH("Punti Bonus Unico",Parametri!$A:$A,0)),0)) -> 0
A11: Sassuolo-Torino | B11: 2 | C11: 1 | D11: 1 | E11: 0 | F11: 2 | G11: 0 | H11: 1 | I11: 1 | J11: 1 | K11: 1 | L11: =IF(OR($B11="",$C11="",D11="",E11=""),"",IF(AND(D11=$B11,E11=$C11),INDEX(Parametri!$B:$B,MATCH("Punti Risultato Esatto",Parametri!$A:$A,0)),IF(SIGN($B11-$C11)=SIGN(D11-E11),INDEX(Parametri!$B:$B,MATCH("Punti Solo Segno",Parametri!$A:$A,0)),0))+IF(AND(SIGN($B11-$C11)=SIGN(D11-E11),(--(SIGN(D11-E11)=SIGN($B11-$C11))+--(SIGN(F11-G11)=SIGN($B11-$C11))+--(SIGN(H11-I11)=SIGN($B11-$C11))+--(SIGN(J11-K11)=SIGN($B11-$C11)))=1),INDEX(Parametri!$B:$B,MATCH("Punti Bonus Unico",Parametri!$A:$A,0)),0)) -> 1 | M11: =IF(OR($B11="",$C11="",F11="",G11=""),"",IF(AND(F11=$B11,G11=$C11),INDEX(Parametri!$B:$B,MATCH("Punti Risultato Esatto",Parametri!$A:$A,0)),IF(SIGN($B11-$C11)=SIGN(F11-G11),INDEX(Parametri!$B:$B,MATCH("Punti Solo Segno",Parametri!$A:$A,0)),0))+IF(AND(SIGN($B11-$C11)=SIGN(F11-G11),(--(SIGN(D11-E11)=SIGN($B11-$C11))+--(SIGN(F11-G11)=SIGN($B11-$C11))+--(SIGN(H11-I11)=SIGN($B11-$C11))+--(SIGN(J11-K11)=SIGN($B11-$C11)))=1),INDEX(Parametri!$B:$B,MATCH("Punti Bonus Unico",Parametri!$A:$A,0)),0)) -> 1 | N11: =IF(OR($B11="",$C11="",H11="",I11=""),"",IF(AND(H11=$B11,I11=$C11),INDEX(Parametri!$B:$B,MATCH("Punti Risultato Esatto",Parametri!$A:$A,0)),IF(SIGN($B11-$C11)=SIGN(H11-I11),INDEX(Parametri!$B:$B,MATCH("Punti Solo Segno",Parametri!$A:$A,0)),0))+IF(AND(SIGN($B11-$C11)=SIGN(H11-I11),(--(SIGN(D11-E11)=SIGN($B11-$C11))+--(SIGN(F11-G11)=SIGN($B11-$C11))+--(SIGN(H11-I11)=SIGN($B11-$C11))+--(SIGN(J11-K11)=SIGN($B11-$C11)))=1),INDEX(Parametri!$B:$B,MATCH("Punti Bonus Unico",Parametri!$A:$A,0)),0)) -> 0 | O11: =IF(OR($B11="",$C11="",J11="",K11=""),"",IF(AND(J11=$B11,K11=$C11),INDEX(Parametri!$B:$B,MATCH("Punti Risultato Esatto",Parametri!$A:$A,0)),IF(SIGN($B11-$C11)=SIGN(J11-K11),INDEX(Parametri!$B:$B,MATCH("Punti Solo Segno",Parametri!$A:$A,0)),0))+IF(AND(SIGN($B11-$C11)=SIGN(J11-K11),(--(SIGN(D11-E11)=SIGN($B11-$C11))+--(SIGN(F11-G11)=SIGN($B11-$C11))+--(SIGN(H11-I11)=SIGN($B11-$C11))+--(SIGN(J11-K11)=SIGN($B11-$C11)))=1),INDEX(Parametri!$B:$B,MATCH("Punti Bonus Unico",Parametri!$A:$A,0)),0)) -> 0
A12: Totale giornata | L12: =SUM(L2:L11) -> 8 | M12: =SUM(M2:M11) -> 6 | N12: =SUM(N2:N11) -> 5 | O12: =SUM(O2:O11) -> 7

Sheet Giornata 3
A1: Partita | B1: Gol Casa Reale | C1: Gol Ospite Reale | D1: Ale Casa | E1: Ale Ospite | F1: Dani Casa | G1: Dani Ospite | H1: Dipa Casa | I1: Dipa Ospite | J1: Mando Casa | K1: Mando Ospite | L1: Punti Ale | M1: Punti Dani | N1: Punti Dipa | O1: Punti Mando
A2: Bologna-Sassuolo | B2: 2 | C2: 2 | D2: 2 | E2: 0 | F2: 1 | G2: 1 | H2: 2 | I2: 1 | J2: 2 | K2: 1 | L2: =IF(OR($B2="",$C2="",D2="",E2=""),"",IF(AND(D2=$B2,E2=$C2),INDEX(Parametri!$B:$B,MATCH("Punti Risultato Esatto",Parametri!$A:$A,0)),IF(SIGN($B2-$C2)=SIGN(D2-E2),INDEX(Parametri!$B:$B,MATCH("Punti Solo Segno",Parametri!$A:$A,0)),0))+IF(AND(SIGN($B2-$C2)=SIGN(D2-E2),(--(SIGN(D2-E2)=SIGN($B2-$C2))+--(SIGN(F2-G2)=SIGN($B2-$C2))+--(SIGN(H2-I2)=SIGN($B2-$C2))+--(SIGN(J2-K2)=SIGN($B2-$C2)))=1),INDEX(Parametri!$B:$B,MATCH("Punti Bonus Unico",Parametri!$A:$A,0)),0)) -> 0 | M2: =IF(OR($B2="",$C2="",F2="",G2=""),"",IF(AND(F2=$B2,G2=$C2),INDEX(Parametri!$B:$B,MATCH("Punti Risultato Esatto",Parametri!$A:$A,0)),IF(SIGN($B2-$C2)=SIGN(F2-G2),INDEX(Parametri!$B:$B,MATCH("Punti Solo Segno",Parametri!$A:$A,0)),0))+IF(AND(SIGN($B2-$C2)=SIGN(F2-G2),(--(SIGN(D2-E2)=SIGN($B2-$C2))+--(SIGN(F2-G2)=SIGN($B2-$C2))+--(SIGN(H2-I2)=SIGN($B2-$C2))+--(SIGN(J2-K2)=SIGN($B2-$C2)))=1),INDEX(Parametri!$B:$B,MATCH("Punti Bonus Unico",Parametri!$A:$A,0)),0)) -> 4 | N2: =IF(OR($B2="",$C2="",H2="",I2=""),"",IF(AND(H2=$B2,I2=$C2),INDEX(Parametri!$B:$B,MATCH("Punti Risultato Esatto",Parametri!$A:$A,0)),IF(SIGN($B2-$C2)=SIGN(H2-I2),INDEX(Parametri!$B:$B,MATCH("Punti Solo Segno",Parametri!$A:$A,0)),0))+IF(AND(SIGN($B2-$C2)=SIGN(H2-I2),(--(SIGN(D2-E2)=SIGN($B2-$C2))+--(SIGN(F2-G2)=SIGN($B2-$C2))+--(SIGN(H2-I2)=SIGN($B2-$C2))+--(SIGN(J2-K2)=SIGN($B2-$C2)))=1),INDEX(Parametri!$B:$B,MATCH("Punti Bonus Unico",Parametri!$A:$A,0)),0)) -> 0 | O2: =IF(OR($B2="",$C2="",J2="",K2=""),"",IF(AND(J2=$B2,K2=$C2),INDEX(Parametri!$B:$B,MATCH("Punti Risultato Esatto",Parametri!$A:$A,0)),IF(SIGN($B2-$C2)=SIGN(J2-K2),INDEX(Parametri!$B:$B,MATCH("Punti Solo Segno",Parametri!$A:$A,0)),0))+IF(AND(SIGN($B2-$C2)=SIGN(J2-K2),(--(SIGN(D2-E2)=SIGN($B2-$C2))+--(SIGN(F2-G2)=SIGN($B2-$C2))+--(SIGN(H2-I2)=SIGN($B2-$C2))+--(SIGN(J2-K2)=SIGN($B2-$C2)))=1),INDEX(Parametri!$B:$B,MATCH("Punti Bonus Unico",Parametri!$A:$A,0)),0)) -> 0
A3: Cagliari-Lecce | B3: 1 | C3: 0 | D3: 1 | E3: 0 | F3: 1 | G3: 1 | H3: 0 | I3: 1 | J3: 1 | K3: 0 | L3: =IF(OR($B3="",$C3="",D3="",E3=""),"",IF(AND(D3=$B3,E3=$C3),INDEX(Parametri!$B:$B,MATCH("Punti Risultato Esatto",Parametri!$A:$A,0)),IF(SIGN($B3-$C3)=SIGN(D3-E3),INDEX(Parametri!$B:$B,MATCH("Punti Solo Segno",Parametri!$A:$A,0)),0))+IF(AND(SIGN($B3-$C3)=SIGN(D3-E3),(--(SIGN(D3-E3)=SIGN($B3-$C3))+--(SIGN(F3-G3)=SIGN($B3-$C3))+--(SIGN(H3-I3)=SIGN($B3-$C3))+--(SIGN(J3-K3)=SIGN($B3-$C3)))=1),INDEX(Parametri!$B:$B,MATCH("Punti Bonus Unico",Parametri!$A:$A,0)),0)) -> 2 | M3: =IF(OR($B3="",$C3="",F3="",G3=""),"",IF(AND(F3=$B3,G3=$C3),INDEX(Parametri!$B:$B,MATCH("Punti Risultato Esatto",Parametri!$A:$A,0)),IF(SIGN($B3-$C3)=SIGN(F3-G3),INDEX(Parametri!$B:$B,MATCH("Punti Solo Segno",Parametri!$A:$A,0)),0))+IF(AND(SIGN($B3-$C3)=SIGN(F3-G3),(--(SIGN(D3-E3)=SIGN($B3-$C3))+--(SIGN(F3-G3)=SIGN($B3-$C3))+--(SIGN(H3-I3)=SIGN($B3-$C3))+--(SIGN(J3-K3)=SIGN($B3-$C3)))=1),INDEX(Parametri!$B:$B,MATCH("Punti Bonus Unico",Parametri!$A:$A,0)),0)) -> 0 | N3: =IF(OR($B3="",$C3="",H3="",I3=""),"",IF(AND(H3=$B3,I3=$C3),INDEX(Parametri!$B:$B,MATCH("Punti Risultato Esatto",Parametri!$A:$A,0)),IF(SIGN($B3-$C3)=SIGN(H3-I3),INDEX(Parametri!$B:$B,MATCH("Punti Solo Segno",Parametri!$A:$A,0)),0))+IF(AND(SIGN($B3-$C3)=SIGN(H3-I3),(--(SIGN(D3-E3)=SIGN($B3-$C3))+--(SIGN(F3-G3)=SIGN($B3-$C3))+--(SIGN(H3-I3)=SIGN($B3-$C3))+--(SIGN(J3-K3)=SIGN($B3-$C3)))=1),INDEX(Parametri!$B:$B,MATCH("Punti Bonus Unico",Parametri!$A:$A,0)),0)) -> 0 | O3: =IF(OR($B3="",$C3="",J3="",K3=""),"",IF(AND(J3=$B3,K3=$C3),INDEX(Parametri!$B:$B,MATCH("Punti Risultato Esatto",Parametri!$A:$A,0)),IF(SIGN($B3-$C3)=SIGN(J3-K3),INDEX(Parametri!$B:$B,MATCH("Punti Solo Segno",Parametri!$A:$A,0)),0))+IF(AND(SIGN($B3-$C3)=SIGN(J3-K3),(--(SIGN(D3-E3)=SIGN($B3-$C3))+--(SIGN(F3-G3)=SIGN($B3-$C3))+--(SIGN(H3-I3)=SIGN($B3-$C3))+--(SIGN(J3-K3)=SIGN($B3-$C3)))=1),INDEX(Parametri!$B:$B,MATCH("Punti Bonus Unico",Parametri!$A:$A,0)),0)) -> 2
A4: Fiorentina-Torino | B4: 1 | C4: 2 | D4: 1 | E4: 1 | F4: 2 | G4: 1 | H4: 1 | I4: 1 | J4: 2 | K4: 1 | L4: =IF(OR($B4="",$C4="",D4="",E4=""),"",IF(AND(D4=$B4,E4=$C4),INDEX(Parametri!$B:$B,MATCH("Punti Risultato Esatto",Parametri!$A:$A,0)),IF(SIGN($B4-$C4)=SIGN(D4-E4),INDEX(Parametri!$B:$B,MATCH("Punti Solo Segno",Parametri!$A:$A,0)),0))+IF(AND(SIGN($B4-$C4)=SIGN(D4-E4),(--(SIGN(D4-E4)=SIGN($B4-$C4))+--(SIGN(F4-G4)=SIGN($B4-$C4))+--(SIGN(H4-I4)=SIGN($B4-$C4))+--(SIGN(J4-K4)=SIGN($B4-$C4)))=1),INDEX(Parametri!$B:$B,MATCH("Punti Bonus Unico",Parametri!$A:$A,0)),0)) -> 0 | M4: =IF(OR($B4="",$C4="",F4="",G4=""),"",IF(AND(F4=$B4,G4=$C4),INDEX(Parametri!$B:$B,MATCH("Punti Risultato Esatto",Parametri!$A:$A,0)),IF(SIGN($B4-$C4)=SIGN(F4-G4),INDEX(Parametri!$B:$B,MATCH("Punti Solo Segno",Parametri!$A:$A,0)),0))+IF(AND(SIGN($B4-$C4)=SIGN(F4-G4),(--(SIGN(D4-E4)=SIGN($B4-$C4))+--(SIGN(F4-G4)=SIGN($B4-$C4))+--(SIGN(H4-I4)=SIGN($B4-$C4))+--(SIGN(J4-K4)=SIGN($B4-$C4)))=1),INDEX(Parametri!$B:$B,MATCH("Punti Bonus Unico",Parametri!$A:$A,0)),0)) -> 0 | N4: =IF(OR($B4="",$C4="",H4="",I4=""),"",IF(AND(H4=$B4,I4=$C4),INDEX(Parametri!$B:$B,MATCH("Punti Risultato Esatto",Parametri!$A:$A,0)),IF(SIGN($B4-$C4)=SIGN(H4-I4),INDEX(Parametri!$B:$B,MATCH("Punti Solo Segno",Parametri!$A:$A,0)),0))+IF(AND(SIGN($B4-$C4)=SIGN(H4-I4),(--(SIGN(D4-E4)=SIGN($B4-$C4))+--(SIGN(F4-G4)=SIGN($B4-$C4))+--(SIGN(H4-I4)=SIGN($B4-$C4))+--(SIGN(J4-K4)=SIGN($B4-$C4)))=1),INDEX(Parametri!$B:$B,MATCH("Punti Bonus Unico",Parametri!$A:$A,0)),0)) -> 0 | O4: =IF(OR($B4="",$C4="",J4="",K4=""),"",IF(AND(J4=$B4,K4=$C4),INDEX(Parametri!$B:$B,MATCH("Punti Risultato Esatto",Parametri!$A:$A,0)),IF(SIGN($B4-$C4)=SIGN(J4-K4),INDEX(Parametri!$B:$B,MATCH("Punti Solo Segno",Parametri!$A:$A,0)),0))+IF(AND(SIGN($B4-$C4)=SIGN(J4-K4),(--(SIGN(D4-E4)=SIGN($B4-$C4))+--(SIGN(F4-G4)=SIGN($B4-$C4))+--(SIGN(H4-I4)=SIGN($B4-$C4))+--(SIGN(J4-K4)=SIGN($B4-$C4)))=1),INDEX(Parametri!$B:$B,MATCH("Punti Bonus Unico",Parametri!$A:$A,0)),0)) -> 0
A5: Frosinone-Venezia | B5: 3 | C5: 2 | D5: 1 | E5: 0 | F5: 2 | G5: 1 | H5: 1 | I5: 1 | J5: 0 | K5: 0 | L5: =IF(OR($B5="",$C5="",D5="",E5=""),"",IF(AND(D5=$B5,E5=$C5),INDEX(Parametri!$B:$B,MATCH("Punti Risultato Esatto",Parametri!$A:$A,0)),IF(SIGN($B5-$C5)=SIGN(D5-E5),INDEX(Parametri!$B:$B,MATCH("Punti Solo Segno",Parametri!$A:$A,0)),0))+IF(AND(SIGN($B5-$C5)=SIGN(D5-E5),(--(SIGN(D5-E5)=SIGN($B5-$C5))+--(SIGN(F5-G5)=SIGN($B5-$C5))+--(SIGN(H5-I5)=SIGN($B5-$C5))+--(SIGN(J5-K5)=SIGN($B5-$C5)))=1),INDEX(Parametri!$B:$B,MATCH("Punti Bonus Unico",Parametri!$A:$A,0)),0)) -> 1 | M5: =IF(OR($B5="",$C5="",F5="",G5=""),"",IF(AND(F5=$B5,G5=$C5),INDEX(Parametri!$B:$B,MATCH("Punti Risultato Esatto",Parametri!$A:$A,0)),IF(SIGN($B5-$C5)=SIGN(F5-G5),INDEX(Parametri!$B:$B,MATCH("Punti Solo Segno",Parametri!$A:$A,0)),0))+IF(AND(SIGN($B5-$C5)=SIGN(F5-G5),(--(SIGN(D5-E5)=SIGN($B5-$C5))+--(SIGN(F5-G5)=SIGN($B5-$C5))+--(SIGN(H5-I5)=SIGN($B5-$C5))+--(SIGN(J5-K5)=SIGN($B5-$C5)))=1),INDEX(Parametri!$B:$B,MATCH("Punti Bonus Unico",Parametri!$A:$A,0)),0)) -> 1 | N5: =IF(OR($B5="",$C5="",H5="",I5=""),"",IF(AND(H5=$B5,I5=$C5),INDEX(Parametri!$B:$B,MATCH("Punti Risultato Esatto",Parametri!$A:$A,0)),IF(SIGN($B5-$C5)=SIGN(H5-I5),INDEX(Parametri!$B:$B,MATCH("Punti Solo Segno",Parametri!$A:$A,0)),0))+IF(AND(SIGN($B5-$C5)=SIGN(H5-I5),(--(SIGN(D5-E5)=SIGN($B5-$C5))+--(SIGN(F5-G5)=SIGN($B5-$C5))+--(SIGN(H5-I5)=SIGN($B5-$C5))+--(SIGN(J5-K5)=SIGN($B5-$C5)))=1),INDEX(Parametri!$B:$B,MATCH("Punti Bonus Unico",Parametri!$A:$A,0)),0)) -> 0 | O5: =IF(OR($B5="",$C5="",J5="",K5=""),"",IF(AND(J5=$B5,K5=$C5),INDEX(Parametri!$B:$B,MATCH("Punti Risultato Esatto",Parametri!$A:$A,0)),IF(SIGN($B5-$C5)=SIGN(J5-K5),INDEX(Parametri!$B:$B,MATCH("Punti Solo Segno",Parametri!$A:$A,0)),0))+IF(AND(SIGN($B5-$C5)=SIGN(J5-K5),(--(SIGN(D5-E5)=SIGN($B5-$C5))+--(SIGN(F5-G5)=SIGN($B5-$C5))+--(SIGN(H5-I5)=SIGN($B5-$C5))+--(SIGN(J5-K5)=SIGN($B5-$C5)))=1),INDEX(Parametri!$B:$B,MATCH("Punti Bonus Unico",Parametri!$A:$A,0)),0)) -> 0
A6: Genoa-Como | B6: 1 | C6: 4 | D6: 1 | E6: 2 | F6: 1 | G6: 3 | H6: 1 | I6: 2 | J6: 0 | K6: 2 | L6: =IF(OR($B6="",$C6="",D6="",E6=""),"",IF(AND(D6=$B6,E6=$C6),INDEX(Parametri!$B:$B,MATCH("Punti Risultato Esatto",Parametri!$A:$A,0)),IF(SIGN($B6-$C6)=SIGN(D6-E6),INDEX(Parametri!$B:$B,MATCH("Punti Solo Segno",Parametri!$A:$A,0)),0))+IF(AND(SIGN($B6-$C6)=SIGN(D6-E6),(--(SIGN(D6-E6)=SIGN($B6-$C6))+--(SIGN(F6-G6)=SIGN($B6-$C6))+--(SIGN(H6-I6)=SIGN($B6-$C6))+--(SIGN(J6-K6)=SIGN($B6-$C6)))=1),INDEX(Parametri!$B:$B,MATCH("Punti Bonus Unico",Parametri!$A:$A,0)),0)) -> 1 | M6: =IF(OR($B6="",$C6="",F6="",G6=""),"",IF(AND(F6=$B6,G6=$C6),INDEX(Parametri!$B:$B,MATCH("Punti Risultato Esatto",Parametri!$A:$A,0)),IF(SIGN($B6-$C6)=SIGN(F6-G6),INDEX(Parametri!$B:$B,MATCH("Punti Solo Segno",Parametri!$A:$A,0)),0))+IF(AND(SIGN($B6-$C6)=SIGN(F6-G6),(--(SIGN(D6-E6)=SIGN($B6-$C6))+--(SIGN(F6-G6)=SIGN($B6-$C6))+--(SIGN(H6-I6)=SIGN($B6-$C6))+--(SIGN(J6-K6)=SIGN($B6-$C6)))=1),INDEX(Parametri!$B:$B,MATCH("Punti Bonus Unico",Parametri!$A:$A,0)),0)) -> 1 | N6: =IF(OR($B6="",$C6="",H6="",I6=""),"",IF(AND(H6=$B6,I6=$C6),INDEX(Parametri!$B:$B,MATCH("Punti Risultato Esatto",Parametri!$A:$A,0)),IF(SIGN($B6-$C6)=SIGN(H6-I6),INDEX(Parametri!$B:$B,MATCH("Punti Solo Segno",Parametri!$A:$A,0)),0))+IF(AND(SIGN($B6-$C6)=SIGN(H6-I6),(--(SIGN(D6-E6)=SIGN($B6-$C6))+--(SIGN(F6-G6)=SIGN($B6-$C6))+--(SIGN(H6-I6)=SIGN($B6-$C6))+--(SIGN(J6-K6)=SIGN($B6-$C6)))=1),INDEX(Parametri!$B:$B,MATCH("Punti Bonus Unico",Parametri!$A:$A,0)),0)) -> 1 | O6: =IF(OR($B6="",$C6="",J6="",K6=""),"",IF(AND(J6=$B6,K6=$C6),INDEX(Parametri!$B:$B,MATCH("Punti Risultato Esatto",Parametri!$A:$A,0)),IF(SIGN($B6-$C6)=SIGN(J6-K6),INDEX(Parametri!$B:$B,MATCH("Punti Solo Segno",Parametri!$A:$A,0)),0))+IF(AND(SIGN($B6-$C6)=SIGN(J6-K6),(--(SIGN(D6-E6)=SIGN($B6-$C6))+--(SIGN(F6-G6)=SIGN($B6-$C6))+--(SIGN(H6-I6)=SIGN($B6-$C6))+--(SIGN(J6-K6)=SIGN($B6-$C6)))=1),INDEX(Parametri!$B:$B,MATCH("Punti Bonus Unico",Parametri!$A:$A,0)),0)) -> 1
A7: Inter-Napoli | B7: 3 | C7: 2 | D7: 2 | E7: 0 | F7: 2 | G7: 1 | H7: 0 | I7: 0 | J7: 2 | K7: 0 | L7: =IF(OR($B7="",$C7="",D7="",E7=""),"",IF(AND(D7=$B7,E7=$C7),INDEX(Parametri!$B:$B,MATCH("Punti Risultato Esatto",Parametri!$A:$A,0)),IF(SIGN($B7-$C7)=SIGN(D7-E7),INDEX(Parametri!$B:$B,MATCH("Punti Solo Segno",Parametri!$A:$A,0)),0))+IF(AND(SIGN($B7-$C7)=SIGN(D7-E7),(--(SIGN(D7-E7)=SIGN($B7-$C7))+--(SIGN(F7-G7)=SIGN($B7-$C7))+--(SIGN(H7-I7)=SIGN($B7-$C7))+--(SIGN(J7-K7)=SIGN($B7-$C7)))=1),INDEX(Parametri!$B:$B,MATCH("Punti Bonus Unico",Parametri!$A:$A,0)),0)) -> 1 | M7: =IF(OR($B7="",$C7="",F7="",G7=""),"",IF(AND(F7=$B7,G7=$C7),INDEX(Parametri!$B:$B,MATCH("Punti Risultato Esatto",Parametri!$A:$A,0)),IF(SIGN($B7-$C7)=SIGN(F7-G7),INDEX(Parametri!$B:$B,MATCH("Punti Solo Segno",Parametri!$A:$A,0)),0))+IF(AND(SIGN($B7-$C7)=SIGN(F7-G7),(--(SIGN(D7-E7)=SIGN($B7-$C7))+--(SIGN(F7-G7)=SIGN($B7-$C7))+--(SIGN(H7-I7)=SIGN($B7-$C7))+--(SIGN(J7-K7)=SIGN($B7-$C7)))=1),INDEX(Parametri!$B:$B,MATCH("Punti Bonus Unico",Parametri!$A:$A,0)),0)) -> 1 | N7: =IF(OR($B7="",$C7="",H7="",I7=""),"",IF(AND(H7=$B7,I7=$C7),INDEX(Parametri!$B:$B,MATCH("Punti Risultato Esatto",Parametri!$A:$A,0)),IF(SIGN($B7-$C7)=SIGN(H7-I7),INDEX(Parametri!$B:$B,MATCH("Punti Solo Segno",Parametri!$A:$A,0)),0))+IF(AND(SIGN($B7-$C7)=SIGN(H7-I7),(--(SIGN(D7-E7)=SIGN($B7-$C7))+--(SIGN(F7-G7)=SIGN($B7-$C7))+--(SIGN(H7-I7)=SIGN($B7-$C7))+--(SIGN(J7-K7)=SIGN($B7-$C7)))=1),INDEX(Parametri!$B:$B,MATCH("Punti Bonus Unico",Parametri!$A:$A,0)),0)) -> 0 | O7: =IF(OR($B7="",$C7="",J7="",K7=""),"",IF(AND(J7=$B7,K7=$C7),INDEX(Parametri!$B:$B,MATCH("Punti Risultato Esatto",Parametri!$A:$A,0)),IF(SIGN($B7-$C7)=SIGN(J7-K7),INDEX(Parametri!$B:$B,MATCH("Punti Solo Segno",Parametri!$A:$A,0)),0))+IF(AND(SIGN($B7-$C7)=SIGN(J7-K7),(--(SIGN(D7-E7)=SIGN($B7-$C7))+--(SIGN(F7-G7)=SIGN($B7-$C7))+--(SIGN(H7-I7)=SIGN($B7-$C7))+--(SIGN(J7-K7)=SIGN($B7-$C7)))=1),INDEX(Parametri!$B:$B,MATCH("Punti Bonus Unico",Parametri!$A:$A,0)),0)) -> 1
A8: Juventus-Milan | B8: 1 | C8: 1 | D8: 1 | E8: 1 | F8: 1 | G8: 1 | H8: 2 | I8: 2 | J8: 2 | K8: 1 | L8: =IF(OR($B8="",$C8="",D8="",E8=""),"",IF(AND(D8=$B8,E8=$C8),INDEX(Parametri!$B:$B,MATCH("Punti Risultato Esatto",Parametri!$A:$A,0)),IF(SIGN($B8-$C8)=SIGN(D8-E8),INDEX(Parametri!$B:$B,MATCH("Punti Solo Segno",Parametri!$A:$A,0)),0))+IF(AND(SIGN($B8-$C8)=SIGN(D8-E8),(--(SIGN(D8-E8)=SIGN($B8-$C8))+--(SIGN(F8-G8)=SIGN($B8-$C8))+--(SIGN(H8-I8)=SIGN($B8-$C8))+--(SIGN(J8-K8)=SIGN($B8-$C8)))=1),INDEX(Parametri!$B:$B,MATCH("Punti Bonus Unico",Parametri!$A:$A,0)),0)) -> 2 | M8: =IF(OR($B8="",$C8="",F8="",G8=""),"",IF(AND(F8=$B8,G8=$C8),INDEX(Parametri!$B:$B,MATCH("Punti Risultato Esatto",Parametri!$A:$A,0)),IF(SIGN($B8-$C8)=SIGN(F8-G8),INDEX(Parametri!$B:$B,MATCH("Punti Solo Segno",Parametri!$A:$A,0)),0))+IF(AND(SIGN($B8-$C8)=SIGN(F8-G8),(--(SIGN(D8-E8)=SIGN($B8-$C8))+--(SIGN(F8-G8)=SIGN($B8-$C8))+--(SIGN(H8-I8)=SIGN($B8-$C8))+--(SIGN(J8-K8)=SIGN($B8-$C8)))=1),INDEX(Parametri!$B:$B,MATCH("Punti Bonus Unico",Parametri!$A:$A,0)),0)) -> 2 | N8: =IF(OR($B8="",$C8="",H8="",I8=""),"",IF(AND(H8=$B8,I8=$C8),INDEX(Parametri!$B:$B,MATCH("Punti Risultato Esatto",Parametri!$A:$A,0)),IF(SIGN($B8-$C8)=SIGN(H8-I8),INDEX(Parametri!$B:$B,MATCH("Punti Solo Segno",Parametri!$A:$A,0)),0))+IF(AND(SIGN($B8-$C8)=SIGN(H8-I8),(--(SIGN(D8-E8)=SIGN($B8-$C8))+--(SIGN(F8-G8)=SIGN($B8-$C8))+--(SIGN(H8-I8)=SIGN($B8-$C8))+--(SIGN(J8-K8)=SIGN($B8-$C8)))=1),INDEX(Parametri!$B:$B,MATCH("Punti Bonus Unico",Parametri!$A:$A,0)),0)) -> 1 | O8: =IF(OR($B8="",$C8="",J8="",K8=""),"",IF(AND(J8=$B8,K8=$C8),INDEX(Parametri!$B:$B,MATCH("Punti Risultato Esatto",Parametri!$A:$A,0)),IF(SIGN($B8-$C8)=SIGN(J8-K8),INDEX(Parametri!$B:$B,MATCH("Punti Solo Segno",Parametri!$A:$A,0)),0))+IF(AND(SIGN($B8-$C8)=SIGN(J8-K8),(--(SIGN(D8-E8)=SIGN($B8-$C8))+--(SIGN(F8-G8)=SIGN($B8-$C8))+--(SIGN(H8-I8)=SIGN($B8-$C8))+--(SIGN(J8-K8)=SIGN($B8-$C8)))=1),INDEX(Parametri!$B:$B,MATCH("Punti Bonus Unico",Parametri!$A:$A,0)),0)) -> 0
A9: Parma-Monza | B9: 1 | C9: 1 | D9: 1 | E9: 1 | F9: 0 | G9: 2 | H9: 1 | I9: 0 | J9: 0 | K9: 0 | L9: =IF(OR($B9="",$C9="",D9="",E9=""),"",IF(AND(D9=$B9,E9=$C9),INDEX(Parametri!$B:$B,MATCH("Punti Risultato Esatto",Parametri!$A:$A,0)),IF(SIGN($B9-$C9)=SIGN(D9-E9),INDEX(Parametri!$B:$B,MATCH("Punti Solo Segno",Parametri!$A:$A,0)),0))+IF(AND(SIGN($B9-$C9)=SIGN(D9-E9),(--(SIGN(D9-E9)=SIGN($B9-$C9))+--(SIGN(F9-G9)=SIGN($B9-$C9))+--(SIGN(H9-I9)=SIGN($B9-$C9))+--(SIGN(J9-K9)=SIGN($B9-$C9)))=1),INDEX(Parametri!$B:$B,MATCH("Punti Bonus Unico",Parametri!$A:$A,0)),0)) -> 2 | M9: =IF(OR($B9="",$C9="",F9="",G9=""),"",IF(AND(F9=$B9,G9=$C9),INDEX(Parametri!$B:$B,MATCH("Punti Risultato Esatto",Parametri!$A:$A,0)),IF(SIGN($B9-$C9)=SIGN(F9-G9),INDEX(Parametri!$B:$B,MATCH("Punti Solo Segno",Parametri!$A:$A,0)),0))+IF(AND(SIGN($B9-$C9)=SIGN(F9-G9),(--(SIGN(D9-E9)=SIGN($B9-$C9))+--(SIGN(F9-G9)=SIGN($B9-$C9))+--(SIGN(H9-I9)=SIGN($B9-$C9))+--(SIGN(J9-K9)=SIGN($B9-$C9)))=1),INDEX(Parametri!$B:$B,MATCH("Punti Bonus Unico",Parametri!$A:$A,0)),0)) -> 0 | N9: =IF(OR($B9="",$C9="",H9="",I9=""),"",IF(AND(H9=$B9,I9=$C9),INDEX(Parametri!$B:$B,MATCH("Punti Risultato Esatto",Parametri!$A:$A,0)),IF(SIGN($B9-$C9)=SIGN(H9-I9),INDEX(Parametri!$B:$B,MATCH("Punti Solo Segno",Parametri!$A:$A,0)),0))+IF(AND(SIGN($B9-$C9)=SIGN(H9-I9),(--(SIGN(D9-E9)=SIGN($B9-$C9))+--(SIGN(F9-G9)=SIGN($B9-$C9))+--(SIGN(H9-I9)=SIGN($B9-$C9))+--(SIGN(J9-K9)=SIGN($B9-$C9)))=1),INDEX(Parametri!$B:$B,MATCH("Punti Bonus Unico",Parametri!$A:$A,0)),0)) -> 0 | O9: =IF(OR($B9="",$C9="",J9="",K9=""),"",IF(AND(J9=$B9,K9=$C9),INDEX(Parametri!$B:$B,MATCH("Punti Risultato Esatto",Parametri!$A:$A,0)),IF(SIGN($B9-$C9)=SIGN(J9-K9),INDEX(Parametri!$B:$B,MATCH("Punti Solo Segno",Parametri!$A:$A,0)),0))+IF(AND(SIGN($B9-$C9)=SIGN(J9-K9),(--(SIGN(D9-E9)=SIGN($B9-$C9))+--(SIGN(F9-G9)=SIGN($B9-$C9))+--(SIGN(H9-I9)=SIGN($B9-$C9))+--(SIGN(J9-K9)=SIGN($B9-$C9)))=1),INDEX(Parametri!$B:$B,MATCH("Punti Bonus Unico",Parametri!$A:$A,0)),0)) -> 1
A10: Roma-Atalanta | L10: =IF(OR($B10="",$C10="",D10="",E10=""),"",IF(AND(D10=$B10,E10=$C10),INDEX(Parametri!$B:$B,MATCH("Punti Risultato Esatto",Parametri!$A:$A,0)),IF(SIGN($B10-$C10)=SIGN(D10-E10),INDEX(Parametri!$B:$B,MATCH("Punti Solo Segno",Parametri!$A:$A,0)),0))+IF(AND(SIGN($B10-$C10)=SIGN(D10-E10),(--(SIGN(D10-E10)=SIGN($B10-$C10))+--(SIGN(F10-G10)=SIGN($B10-$C10))+--(SIGN(H10-I10)=SIGN($B10-$C10))+--(SIGN(J10-K10)=SIGN($B10-$C10)))=1),INDEX(Parametri!$B:$B,MATCH("Punti Bonus Unico",Parametri!$A:$A,0)),0)) | M10: =IF(OR($B10="",$C10="",F10="",G10=""),"",IF(AND(F10=$B10,G10=$C10),INDEX(Parametri!$B:$B,MATCH("Punti Risultato Esatto",Parametri!$A:$A,0)),IF(SIGN($B10-$C10)=SIGN(F10-G10),INDEX(Parametri!$B:$B,MATCH("Punti Solo Segno",Parametri!$A:$A,0)),0))+IF(AND(SIGN($B10-$C10)=SIGN(F10-G10),(--(SIGN(D10-E10)=SIGN($B10-$C10))+--(SIGN(F10-G10)=SIGN($B10-$C10))+--(SIGN(H10-I10)=SIGN($B10-$C10))+--(SIGN(J10-K10)=SIGN($B10-$C10)))=1),INDEX(Parametri!$B:$B,MATCH("Punti Bonus Unico",Parametri!$A:$A,0)),0)) | N10: =IF(OR($B10="",$C10="",H10="",I10=""),"",IF(AND(H10=$B10,I10=$C10),INDEX(Parametri!$B:$B,MATCH("Punti Risultato Esatto",Parametri!$A:$A,0)),IF(SIGN($B10-$C10)=SIGN(H10-I10),INDEX(Parametri!$B:$B,MATCH("Punti Solo Segno",Parametri!$A:$A,0)),0))+IF(AND(SIGN($B10-$C10)=SIGN(H10-I10),(--(SIGN(D10-E10)=SIGN($B10-$C10))+--(SIGN(F10-G10)=SIGN($B10-$C10))+--(SIGN(H10-I10)=SIGN($B10-$C10))+--(SIGN(J10-K10)=SIGN($B10-$C10)))=1),INDEX(Parametri!$B:$B,MATCH("Punti Bonus Unico",Parametri!$A:$A,0)),0)) | O10: =IF(OR($B10="",$C10="",J10="",K10=""),"",IF(AND(J10=$B10,K10=$C10),INDEX(Parametri!$B:$B,MATCH("Punti Risultato Esatto",Parametri!$A:$A,0)),IF(SIGN($B10-$C10)=SIGN(J10-K10),INDEX(Parametri!$B:$B,MATCH("Punti Solo Segno",Parametri!$A:$A,0)),0))+IF(AND(SIGN($B10-$C10)=SIGN(J10-K10),(--(SIGN(D10-E10)=SIGN($B10-$C10))+--(SIGN(F10-G10)=SIGN($B10-$C10))+--(SIGN(H10-I10)=SIGN($B10-$C10))+--(SIGN(J10-K10)=SIGN($B10-$C10)))=1),INDEX(Parametri!$B:$B,MATCH("Punti Bonus Unico",Parametri!$A:$A,0)),0))
